Workbook
Name Broker_and_Agent_Management: 'Dropdown List'!$K$2:$K$22
Name Claims: 'Dropdown List'!$B$2:$B$22
Name Evaluation: 'Dropdown List'!$H$2:$H$22
Name Functions: 'Dropdown List'!$A$2:$A$22
Name Information_Gathering_and_Risk_Selection: 'Dropdown List'!$L$2:$L$22
Name Initiation: 'Dropdown List'!$F$2:$F$22
Name Investigation: 'Dropdown List'!$G$2:$G$22
Name Issuance: 'Dropdown List'!$O$2:$O$22
Name Legal_Support: 'Dropdown List'!$V$2:$V$22
Name Legal_Support_Services: 'Dropdown List'!$E$2:$E$22
Name Litigation_and_Resolution: 'Dropdown List'!$I$2:$I$22
Name Office_of_General_Counsel: 'Dropdown List'!$W$2:$W$22
Name Policy_Servicing: 'Dropdown List'!$P$2:$P$22
Name Premium_Audit: 'Dropdown List'!$Q$2:$Q$22
Name Pricing_and_Negotiation: 'Dropdown List'!$N$2:$N$22
Name Procurement: 'Dropdown List'!$X$2:$X$22
Name Risk_Assessment_and_Rating: 'Dropdown List'!$M$2:$M$22
Name Risk_Control: 'Dropdown List'!$R$2:$R$22
Name Sales: 'Dropdown List'!$S$2:$S$22
Name Sales_and_Customer_Support: 'Dropdown List'!$T$2:$T$22
Name Sales_and_Service: 'Dropdown List'!$D$2:$D$22
Name Service_and_Upsell: 'Dropdown List'!$U$2:$U$22
Name Slicer_Business_Lines: #N/A
Name Slicer_Client: #N/A
Name Slicer_Client_Geography: #N/A
Name Slicer_Country: #N/A
Name Slicer_EXL_Delivery_Location: #N/A
Name Slicer_Function__L1: #N/A
Name Slicer_LOB___Product_Type: #N/A
Name Slicer_Work_Type: #N/A
Name Subrogation_and_Compliance: 'Dropdown List'!$J$2:$J$22
Name Underwriting_and_UW_Support: 'Dropdown List'!$C$2:$C$22

Sheet 1. General Instructions
B1: General Instructions
B3: 1) | C3: Do not modify the 'Data Collection' sheet in any way.
B4: 2) | C4: Do not paste values in the dropdowns. If you are unable to find an option from the drop down menu please provide details using 'Insert Comment' function
B5: 3) | C5: Do not merge cells. In the event a data point applies to more than 1 process, please enter on separate row items and/ or add details using the 'Insert Comment' function
B6: 4) | C6: In the event additional details need to be shared and you do not see a provision for it, please add using 'Insert Comment' and highlight the cell
B7: 5) | C7: Please include details for processes we performed in the past but are no longer active/ ramped down. There is a provision to call out their status appropriately in the sheet
B8: 6) | C8: Please add rows as required depending on the number of processes. The template currently has provision to include details for 100 processes
B9: 7) | C9: When updating LOB details, please use the abbreviations provided below and be consistent. Also, if you use additional abbreviations please share them on email when sending the updated file
B10: 8) | C10: For cells that may need multiple data point please only use a 'comma' as a seperator
B12: Field Description and Input Instructions
B14: # | C14: Field Names | D14: Field Type | E14: Description
B15: GENERAL OVERVIEW
B16: 1 | C16: Client | D16: Drop Down | E16: Please select your client name from the drop down menu
B17: 2 | C17: Client Description | D17: Drop Down | E17: This is a formula driven cell. Once you selct the clinet name, the drop down menu will only provide the corresponding 'Client Description' to select. Please choose and move forward
B18: 3 | C18: Client Geography | D18: Drop Down | E18: Please select the location from the drop down menu. If a location needs to be added, please insert a comment providing details, and we will add. Do Not modify the sheet.
B19: 4 | C19: EXL Delivery Location | D19: Drop Down | E19: Please select the location from the drop down menu. If a location needs to be added, please insert a comment providing details, and we will add. Do Not modify the sheet.
B20: 5 | C20: EXL Process Manager | D20: Free Text | E20: Please state the Process Manager name
B21: 6 | C21: Relationship Tenure | D21: Free Text | E21: Please state the number of years (upto 2 decimal places) your process has been active with EXL.
B22: 7 | C22: Current Status | D22: Drop Down | E22: Please select the appropriate status from drop down menu
B23: 8 | C23: Function (L1) | D23: Drop Down | E23: Please select the appropriate function from the drop down menu
B24: 9 | C24: Function (L2) | D24: Drop Down | E24: This is a formula driven cell. Once you selct the Function (L1), the drop down menu will only provide corresponding options. Please select the most appropriate option and move forward
B25: 10 | C25: Process Name (L3) | D25: Drop Down | E25: This is a formula driven cell. Once you selct the Function (L2), the drop down menu will only provide corresponding options. Please select the most appropriate option and move forward
B26: 11 | C26: Task Name | D26: Free Text | E26: Please state the task name using comon industry key words such as FNOL, Endorsements, Vendor Payments etc. that best describes the task
B27: 12 | C27: Process Description/ High-level steps | D27: Free Text | E27: Please provide a description of the work performed. Use bullet points to detail the process, with not more than 10 bullet points
... B36: 21 | C36: Ramp Duration | D36: Free Text | E36: Please state the number of weeks required for live production to achieve steady state. Please use the below format while updating: 1) If ramp uses complete weeks then state the exact number of weeks. Example - 2 2) If ramp spills over to a portion of the following week state a range. Example - 3 to 4
B37: STAFFING & PRICING
B38: 22 | C38: Pricing Model | D38: Drop Down | E38: Please selct the appropriate pricing model from the drop down menu
B39: 23 | C39: Annual Rate | D39: Free Text | E39: Please provide details of the annual rate
B40: 24 | C40: Billable FTEs | D40: Free Text | E40: Please state the billable FTE count (upto 2 decimal places)
B41: 25 | C41: SME + QA + Trainer | D41: Free Text | E41: Please state the combined count of SME+QA+Trainer supporting the process. Do not include buffer staff. (upto 2 decimal places)
B42: 26 | C42: Supervisor | D42: Free Text | E42: Please state the supervisor FTE count supporting the process (upto 2 decimal places)
B43: 27 | C43: Roster HC | D43: Free Text | E43: Please state the buffer staff count supporting the process (upto 2 decimal places)
B44: PERFORMANCE MANAGEMENT
B45: 28 | C45: Work Allocation | D45: Drop Down | E45: Please select the appropriate work allocation method from the drop down menu
B46: 29 | C46: Average Monthly Volume | D46: Free Text | E46: Please state the combined average monthly volume across all LOBs serviced in the process
B47: 30 | C47: Avergae Monthly Volume by LOB | D47: Free Text | E47: Please state a breakdown of average monthly volume by LOB. If this data is not tracked/ available please enter "NA"
B48: 31 | C48: Peak Volume Months | D48: Free Text | E48: Please state details of peak volume months; use the format - MMM, Volume. Example - Jan, Feb, 6300 If there are no peak months please enter "NA"
B49: 32 | C49: Process AHT | D49: Free Text | E49: Please state the process AHT as agreed with yur client (in mins and upto 2 deciaml places)
B50: 33 | C50: Timeliness SLA | D50: Free Text | E50: Please state the timeliness SLA as agreed with your client
B51: 34 | C51: Quality SLA | D51: Free Text | E51: Please state the quality SLA as agreed with your client
...

Sheet Sheet1
A2: Sum of Total Staff | B2: Column Labels
A3: Row Labels | B3: Colombia | C3: India | D3: Philippines | E3: South Africa | F3: Grand Total
A4: Claims | B4: 13 | C4: 1855.4288 | D4: 3498.24 | E4: 477.98 | F4: 5844.6488
A5: Evaluation | C5: 102.41875 | D5: 178.77 | E5: 2.09 | F5: 283.27875
A6: Initiation | B6: 13 | C6: 761.42415 | D6: 3231.74 | E6: 446.44 | F6: 4452.6042
A7: Investigation | C7: 200.29463 | D7: 39.2 | E7: 19.59 | F7: 259.08463
A8: Litigation and Resolution | C8: 572.94639 | D8: 36.53 | E8: 6.18 | F8: 615.65639
A9: Subrogation and Compliance | C9: 218.34487 | D9: 12 | E9: 3.68 | F9: 234.02487
A10: Legal Support Services | C10: 31 | F10: 31
A11: Legal Support | C11: 19 | F11: 19
A12: Procurement | C12: 12 | F12: 12
A13: Sales and Service | B13: 20 | C13: 110 | D13: 345 | E13: 447 | F13: 922
A14: Sales and Customer Support | B14: 20 | C14: 110 | D14: 345 | E14: 65 | F14: 540
A15: Service and Upsell | E15: 382 | F15: 382
A16: Underwriting and UW Support | C16: 2147.3888 | D16: 6 | E16: 109 | F16: 2262.3888
A17: Broker and Agent Management | C17: 49.51 | F17: 49.51
A18: Information Gathering and Risk Selection | C18: 411.46 | E18: 0 | F18: 411.46
A19: Issuance | C19: 492.86374 | F19: 492.86374
A20: Policy Servicing | C20: 925.35498 | D20: 5 | E20: 109 | F20: 1039.355
A21: Premium Audit | C21: 29.93 | F21: 29.93
A22: Risk Assessment and Rating | C22: 238.27012 | F22: 238.27012
A23: Risk Control | D23: 1 | F23: 1
A24: Grand Total | B24: 33 | C24: 4143.8176 | D24: 3849.24 | E24: 1033.98 | F24: 9060.0376

Sheet 2. Data Collection
A1: Client | B1: Client Description | C1: Client Geography | D1: EXL Delivery Location | E1: Country | F1: EXL Process Manager | G1: Relationship Tenure (years) | H1: Current Status | I1: Function (L1) | J1: Function (L2) | K1: Process Name (L3) | L1: Task Name | M1: Process Description/ High-level steps | N1: Business Lines | O1: LOB / Product Type | P1: LOB Breakup | Q1: Market Type | R1: Work Type | S1: Complexity Level | T1: Pre-Process Training Duration (weeks) | U1: Process Training Duration (weeks) | V1: Ramp Duration (weeks) | W1: Pricing Model | X1: Pricing Currency | Y1: Annual Rate | Z1: Billable FTEs | AA1: SME + QA + Trainer | AB1: Supervisor | AC1: Roster HC (Only Buffer Resources) | AD1: Total Staff | AE1: Roster % | AF1: Average Monthly Volume | AG1: Avergae Monthly Volume by LOB | AH1: Peak Volume Months | AI1: Process AHT (Minutes) | AJ1: Timeliness SLA | AK1: Quality SLA | AL1: Quality Methodology | AM1: Additional Metrics - 1 | AN1: Additional Metrics - 2 | AO1: Pain Points | AP1: Key Customer / Business Outcomes Impacted | AQ1: Implemented Digital Solutions (if any) | AR1: Summary of Implemented Solution | AS1: Expected/ Derived Benefits | AT1: Planned/Ongoing Digital Solutions (if any) | AU1: Summary of Planned Solutions | AV1: Expected Benefits | AW1: Any client led innovation / transformation | AX1: Suppliers | AY1: Input Format | AZ1: Standardization level of Inputs | BA1: % split of Input types | BB1: Output Format | BC1: Customers | BD1: Client Applications / Admin Systems
A2: Free Text | B2: Free Text | C2: Drop Down | D2: Drop Down | E2: Autopopulated Field | F2: Free Text | G2: Free Text | H2: Drop Down | I2: Drop Down | J2: Drop Down | K2: Drop Down | L2: Free Text | M2: Free Text | N2: Drop Down | O2: Drop Down | P2: Free Text | Q2: Drop Down | R2: Drop Down | S2: Drop Down | T2: Free Text | U2: Free Text | V2: Free Text | W2: Drop Down | X2: Drop Down | Y2: Free Text | Z2: Free Text | AA2: Free Text | AB2: Free Text | AC2: Free Text | AD2: Free Text | AE2: Free Text | AF2: Free Text | AG2: Free Text | AH2: Free Text | AI2: Free Text | AJ2: Free Text | AK2: Free Text | AL2: Drop Down | AM2: Free Text | AN2: Free Text | AO2: Free Text | AP2: Free Text | AQ2: Free Text | AR2: Free Text | AS2: Free Text | AT2: Free Text | AU2: Free Text | AV2: Free Text | AW2: Free Text | AX2: Free Text | AY2: Free Text | AZ2: Drop Down | BA2: Free Text | BB2: Free Text | BC2: Free Text | BD2: Free Text
A3: Nationwide | B3: Fortune 500 & Large US Insurance carrier | C3: North America | D3: Manila, PHP | E3: =VLOOKUP(D3,'Dropdown List'!$F$26:$G$40,2,0) -> Philippines | F3: Chona Mae Catimbang | G3: 1 year | H3: Active | I3: Claims | J3: Initiation | K3: First Notice of Loss Calls | L3: PL FNOL Auto | M3: Receive first notice of loss calls for auto collisions, accidents and any type of loss related to automobile/vehicle Receive calls from policyholders on FNOL inquiries and existing claims Receive calls for large loss greater than 10,000 USD | N3: Personal | O3: Auto | P3: Auto | Q3: All | R3: Voice | S3: L3 | T3: 4 | U3: 6 | V3: 16 | W3: Transaction Based | X3: USD | Y3: 4372 | Z3: 30 | AA3: 10 | AB3: 4 | AC3: 30 | AD3: =SUM(Z3:AC3) -> 74 | AE3: =AC3/AD3 -> 0.40540541 | AI3: 574 | AK3: CSM 95% Handling 85% CSM 90% | AL3: DPU – Defect Per Unit | AO3: Quality methodology | AX3: Onshore clients | AY3: FNOL, Inquiry | AZ3: Unstructured | BB3: Multiple | BC3: Policyholders, agent, 3rd party | BD3: Claims Center
A4: Nationwide | B4: Fortune 500 & Large US Insurance carrier | C4: North America | D4: Cebu, PHP | E4: =VLOOKUP(D4,'Dropdown List'!$F$26:$G$40,2,0) -> Philippines | F4: Chona Mae Catimbang | G4: 1 year | H4: Active | I4: Claims | J4: Initiation | K4: First Notice of Loss Calls | L4: PL FNOL Auto | M4: Receive first notice of loss calls for auto collisions, accidents and any type of loss related to automobile/vehicle Receive calls from policyholders on FNOL inquiries and existing claims Receive calls for large loss greater than 10,000 USD | N4: Personal | O4: Auto | P4: Auto | Q4: All | R4: Voice | S4: L3 | T4: 4 | U4: 6 | V4: 16 | W4: Transaction Based | X4: USD | Y4: 4372 | Z4: 75 | AA4: 10 | AB4: 7 | AC4: 30 | AD4: =SUM(Z4:AC4) -> 122 | AE4: =AC4/AD4 -> 0.24590164 | AI4: 574 | AK4: CSM 95% Handling 85% CSM 90% | AL4: DPU – Defect Per Unit | AO4: Quality methodology | AX4: Onshore clients | AY4: FNOL, Inquiry | AZ4: Unstructured | BB4: Multiple | BC4: Policyholders, agent, 3rd party | BD4: Claims Center
A5: Nationwide | B5: Fortune 500 & Large US Insurance carrier | C5: North America | D5: Manila, PHP | E5: =VLOOKUP(D5,'Dropdown List'!$F$26:$G$40,2,0) -> Philippines | F5: Raymond Perez | G5: 1 year | H5: Active | I5: Claims | J5: Initiation | K5: First Notice of Loss Calls | L5: PL FNOL Property | M5: Receive first notice of loss calls for businessproperty loss - weather related, wind hail, hurricane, tornadoes etc. Receive calls from policyholders on FNOL incuiries and existing claims | N5: Personal | O5: Property | P5: Property | Q5: All | R5: Voice | S5: L3 | T5: 4 | U5: 6 | V5: 11 | W5: Transaction Based | X5: USD | Y5: 4372 | Z5: 30 | AA5: 5 | AB5: 2 | AC5: 3 | AD5: =SUM(Z5:AC5) -> 40 | AE5: =AC5/AD5 -> 0.075 | AI5: 574 | AK5: CSM 95% Handling 85% CSM 90% | AL5: DPU – Defect Per Unit | AO5: Quality methodology | AX5: Onshore clients | AY5: FNOL, Inquiry | AZ5: Unstructured | BB5: Multiple | BC5: Policyholders, agent, 3rd party | BD5: Claims Center
A6: Nationwide | B6: Fortune 500 & Large US Insurance carrier | C6: North America | D6: Cebu, PHP | E6: =VLOOKUP(D6,'Dropdown List'!$F$26:$G$40,2,0) -> Philippines | F6: Raymond Perez | G6: 1 year | H6: Active | I6: Claims | J6: Initiation | K6: First Notice of Loss Calls | L6: PL FNOL Property | M6: Receive first notice of loss calls for businessproperty loss - weather related, wind hail, hurricane, tornadoes etc. Receive calls from policyholders on FNOL incuiries and existing claims | N6: Personal | O6: Property | P6: Property | Q6: All | R6: Voice | S6: L3 | T6: 4 | U6: 6 | V6: 11 | W6: Transaction Based | X6: USD | Y6: 4372 | Z6: 25 | AA6: 5 | AB6: 2 | AC6: 3 | AD6: =SUM(Z6:AC6) -> 35 | AE6: =AC6/AD6 -> 0.085714286 | AI6: 574 | AK6: CSM 95% Handling 85% CSM 90% | AL6: DPU – Defect Per Unit | AO6: Quality methodology | AX6: Onshore clients | AY6: FNOL, Inquiry | AZ6: Unstructured | BB6: Multiple | BC6: Policyholders, agent, 3rd party | BD6: Claims Center
A7: Nationwide | B7: Fortune 500 & Large US Insurance carrier | C7: North America | D7: Manila, PHP | E7: =VLOOKUP(D7,'Dropdown List'!$F$26:$G$40,2,0) -> Philippines | F7: Raymond Perez | G7: 1 year | H7: Active | I7: Claims | J7: Initiation | K7: First Notice of Loss Calls | L7: Business inquiry calls | M7: Receive calls from policyholders on FNOL inquiries and existing claims | N7: Specialty | O7: Multi/ Combination | P7: Multiple | Q7: All | R7: Voice | S7: L3 | T7: 4 | U7: 6 | V7: 11 | W7: Transaction Based | X7: USD | Y7: 5247 | Z7: 30 | AA7: 3 | AB7: 1 | AC7: 3 | AD7: =SUM(Z7:AC7) -> 37 | AE7: =AC7/AD7 -> 0.081081081 | AI7: 380 | AK7: 0.95 | AL7: Weighted DPO – Weighted Defect Per Opportunity | AO7: Quality methodology | AX7: Onshore clients | AY7: FNOL, Inquiry | AZ7: Unstructured | BB7: Multiple | BC7: Policyholders, agent, 3rd party | BD7: Claims Center
A8: Nationwide | B8: Fortune 500 & Large US Insurance carrier | C8: US | D8: Manila, PHP | E8: =VLOOKUP(D8,'Dropdown List'!$F$26:$G$40,2,0) -> Philippines | F8: David De Vera | G8: 1 Year | H8: Active | I8: Claims | J8: Initiation | K8: First Notice of Loss Calls | L8: Business FNOL Inquiry calls | M8: Receive first notice of loss calls for business auto and property loss - weather related, wind hail, hurricane, tornadoes etc. Receive calls from policyholders on FNOL incuiries and existing claims | N8: Commercial | O8: Multi/ Combination | P8: Auto, Property | Q8: All | R8: Voice | S8: L3 | T8: 4 | U8: 6 | V8: 11 | W8: Transaction Based | X8: USD | Y8: 5247 | Z8: 30 | AA8: 2 | AB8: 1 | AC8: 3 | AD8: =SUM(Z8:AC8) -> 36 | AE8: =AC8/AD8 -> 0.083333333 | AK8: 0.9 | AL8: DPU – Defect Per Unit | AO8: Quality methodology | AX8: Onshore clients | AY8: FNOL, Inquiry | AZ8: Unstructured | BB8: Multiple | BC8: Policyholders, agent, 3rd party | BD8: Claims Center
A9: Nationwide | B9: Fortune 500 & Large US Insurance carrier | C9: US | D9: Manila, PHP | E9: =VLOOKUP(D9,'Dropdown List'!$F$26:$G$40,2,0) -> Philippines | F9: David De Vera | G9: 1 Year | H9: Active | I9: Claims | J9: Initiation | K9: First Notice of Loss Calls | L9: Business FNOL Inquiry calls | M9: Receive first notice of loss calls for business auto and property loss - weather related, wind hail, hurricane, tornadoes etc. Receive calls from policyholders on FNOL incuiries and existing claims | N9: Commercial | O9: Multi/ Combination | P9: Auto, Property | Q9: All | R9: Voice | S9: L3 | T9: 4 | U9: 6 | V9: 11 | W9: Transaction Based | X9: USD | Y9: 5247 | Z9: 25 | AA9: 2 | AB9: 1 | AC9: 3 | AD9: =SUM(Z9:AC9) -> 31 | AE9: =AC9/AD9 -> 0.096774194 | AK9: 0.95 | AL9: Weighted DPO – Weighted Defect Per Opportunity | AO9: Quality methodology | AX9: Onshore clients | AY9: FNOL, Inquiry | AZ9: Unstructured | BB9: Multiple | BC9: Policyholders, agent, 3rd party | BD9: Claims Center
A10: Nationwide | B10: Fortune 500 & Large US Insurance carrier | C10: US | D10: Manila, PHP | E10: =VLOOKUP(D10,'Dropdown List'!$F$26:$G$40,2,0) -> Philippines | F10: David De Vera | G10: 1 Year | H10: Inactive | I10: Claims | J10: Initiation | K10: First Notice of Loss Calls | L10: FNOL, Inquiry calls | M10: Receive first notice of loss calls for business auto and property loss - weather related, wind hail, hurricane, tornadoes etc. Receive calls from policyholders on FNOL incuiries and existing claims | N10: Personal | O10: Multi/ Combination | P10: Auto, Property | Q10: All | R10: Voice | S10: L3 | T10: 4 | U10: 6 | V10: 20 | W10: Transaction Based | X10: USD | Y10: 5247 | Z10: 19 | AA10: 1 | AB10: 2 | AC10: 2 | AD10: =SUM(Z10:AC10) -> 24 | AE10: =AC10/AD10 -> 0.083333333 | AK10: 0.95 | AL10: Weighted DPO – Weighted Defect Per Opportunity | AO10: Quality methodology | AX10: Onshore clients | AY10: FNOL, Inquiry | AZ10: Unstructured | BB10: Multiple | BC10: Policyholders, agent, 3rd party | BD10: Claims Center
A11: Nationwide | B11: Fortune 500 & Large US Insurance carrier | C11: US | D11: Manila, PHP | E11: =VLOOKUP(D11,'Dropdown List'!$F$26:$G$40,2,0) -> Philippines | F11: John Pin Onrade | G11: 1 Year | H11: Active | I11: Claims | J11: Initiation | K11: Data entry | L11: CPT-Imaging + DESK, PRN, URS, CLME | File Claimant Carrier FNOL | File Copy/File Request | General Admin + Box | General Admin + Document Uploads | West Virginia–Mass Mailing Task | General Admin + Imaging | General Admin + Policy Request | Genesys Call Recording / Review | General Admin + Litigation Solutions | General Admin + Child Liens | General Admin + Escheat | General Admin + PL Sales Inquiries | ID Admin / Ordering + ClaimCenter Changes | ID Admin / Ordering + Ordering System Access / IDs | ID Admin / Ordering + Call Center Equipment / Supplies (except New Hire) | ID Admin / Ordering + Call Center New Hire / Term / Transfer | ID Admin / Ordering + New Hire Equipment and Access | ID Admin / Ordering + Order Supplies / Equipment | ID Admin / Ordering + Surplus | ID Admin / Ordering + Terminations | Senior Admin + Manual Check Ordering / Maintenance | Senior Admin + TX DMV | M11: Forwarding to the right department. Sorting the queries that mailbox is receiving. Claimant carrier requests assist the adjuster with reporting FNOL to the claimant (other party in a claim). When a claim has already been filed with the Claimant Carrier, these requests assist in obtaining additional claim information. A File Copy request is received as an activity through Claim Center when an adjuster requests a complete copy of the claim file materials (Claim Center documents, notes, medical bills, records, etc) This task covers the process for uploading images into Claim Center when they are received from LITSPEC mailbox. Admin processers will be getting the box link and passwords to open and retrieve the documents. This task covers the process for uploading images into Claim Center when they are received from Complex, LSI and Claims Adjusters. These are mostly medical related documents - medical records and/or bills. This task is received as an activity through Claim Center in the form of a Policy Request. The imaging task consists of imaging the claim notes, documents, and emails into the claim file for adjusters. This is to ensure that a claim is properly handled with all the required documentation be attached to the claim. Claim notes and documentation can be received through email that provide information from estimators, vendors, and customers. Policy Request is received as an activity through Claim Center. The process often starts with the adjuster requesting policy documents such as certified declaration page, the policy jacket and/or endorsements. This task covers request for a Genesys call recording to be pulled and uploaded to Claim Center. Adjuster send requests to Litigation Solutions for documents pertaining to their claim file for medical records, employment records, surveillance, Xrays etc. LitSol will send these requests on to assist with uploading the documents to the claim files. To determine if any liens exist To review the check status to determine a resolution to the check Our sales partners will send an email to connect with claim's leader regarding an escalated claim issue. This request is being initiated by PL Claims Organizations to Everything Admin for assistance with ClaimCenter changes, access ordering, Call Center needed equipment and supplies, requesting new access for new hires, enabling or deactivating accesses for transfers and deactivating access requests for Call Centers, requesting new access, ordering supplies and equipment for new hires, assistance with retrieval of devices and assistance with Terminations This is the process for sending packs to field or CAT adjusters. Assistance in provided for Adding, Changing, or Deleting authorized users and Password Resets for TX DMV | N11: Personal | O11: Multi/ Combination | P11: Auto | Q11: All | R11: Blended | S11: L2 | T11: 2 | U11: 5 | V11: 6 | W11: FTE Based | X11: USD | Y11: 31927.5 | Z11: 28 | AA11: 3 | AB11: 2 | AC11: 13 | AD11: =SUM(Z11:AC11) -> 46 | AE11: =AC11/AD11 -> 0.2826087 | AK11: 0.9 | AL11: DPU – Defect Per Unit | AO11: Quality methodology | AX11: Onshore clients | AY11: Admin Voice + Foundational | AZ11: Unstructured | BB11: Multiple | BC11: Policyholders, agent, 3rd party | BD11: Outlook, Ariba, EA Sharepoint, MyTech, Service Now, IIQ, Agero, Mozart, DPA, ARMS, Knowledge Advance, EFileNet, Onboarding Guide Excel
A12: Nationwide | B12: Fortune 500 & Large US Insurance carrier | C12: US | D12: Manila, PHP | E12: =VLOOKUP(D12,'Dropdown List'!$F$26:$G$40,2,0) -> Philippines | F12: John Pin Onrade | G12: 1 Year | H12: Active | I12: Claims | J12: Initiation | K12: Claim Setup and assignment | L12: Mitchell – No Match (Previously known as General Admin + AIS No Match) | General Admin + Iron Mountain / GRM Requests | General Admin + NY DMV | General Admin + SIU Blue | PIP (Michigan Provider) | Mitchell Payments - Issue Payments (Previously known as General Admin + AIS Issue Payment) | General Admin + eSubro Hub | General Admin + Kentucky Arbitrations | General Admin + LitFax | General Admin + MD Supplements | General Admin + NICB Payments | General Admin + NWSOP | General Admin + Respondent Arbitrations | General Admin + SUB UM/Insure No Pay | Reporting + ARB Report | MD Fire and Theft Dispatching | SERO Dispatching | WCZASIGN Dispatching Assignment | SPECTOYS & SPECOYS Network Assignment | NECZ Dispatching | National Recovery/Subrogation Dispatching | ClaimCenter Proxy Assignments | MD Total Loss Dispatching | CCC1 Portal Bucket Assignments | M12: A Doc ID is considered a Claim No Match when the information provided on the bill or in the accompanying documentation does not match the same information in the Nationwide claim feed received by Mitchell or there are multiple dates of loss. Review request to see who the NY DMV search is to be run for. Requestor may be asking for a VIN search or a license plate search. This provides instructions for pulling a credit report from TransUnion. Claims Associates requests checks be written to PIP providers for services completed. Bills are assigned to Admins in Mitchell each day. Once all bills have been submitted, refer to Bill Assignment Tracker spreadsheet as Claim Number, MCCA, and Bill Number will be needed to issue each payment. Admin review all incoming demands and distributes accordingly in E-Subrogation Hub (ESH) and mark the Productivity Tracker Spreadsheet. Kentucky Arbitrations are received from the Kentucky Insurance Arbitration Association. Admins assign the arbitrations to specific adjusters who have been trained as independent arbitrators for KY PIP claims involving other insurance companies. Once a claim has gone into Litigation, Nationwide will be served through NWSOP. A request will be submitted via email to LITFAX@nationwide.comemail link from NWSOP to have the claim reassigned to a Litigation Adjuster. This outlines Material Damage (MD) Supplements and invoices received for additional repairs needed. The Nationwide Crime Bureau submits fees that are due for services related to Claims investigations. Suits/Complaints and other documents served upon Nationwide through its registered agent, CSC, are received via the LITFAX shared mailbox (LITFAX@nationwide.com). However, some suits/complaints may be forwarded to LITFAX from another source, such as an adjuster or director. In general, the documents are processed by uploading them to the claim and assigning a new adjuster or notifying an existing adjuster. Most sections of this KA apply to suit/complaint documents. This workflow applies to all states EXCEPT the following: AL, AR, IL, IN, KY, MI, MS, OH, TN, WV. For those states, LITFAX Assignments (PL) would be applicable. Processing new respondent arbitration files to be assigned for response to a National Recovery Associate. Assigning and completing of recovery tasks placed in recovery queues. Running report in the Arbitration Forums website to determine all unanswered respondent arbitration files due within 48 hours and notifying the handling associate. This covers the processes for assigning claims from ClaimCenter that cannot be automated and file assigning Fire & Theft claims to adjusters. This covers the processes for reassigning claims from requests received from parties requesting reconsideration of the claims decision on the BI coverage. This covers the processes for assigning claims from ClaimCenter that cannot be automated and file assigning CICS claims to adjusters in the Northeast claims area. This covers the processes for manually assigning claims to subrogation Claims Associates. This covers the processes for assigning claims from multiple Proxies within ClaimCenter. Each Proxy has specific handling procedures and assignment criteria. This overs the processes for assigning MD Total Loss claims from ClaimCenter that cannot be automated and assigning claims sent in via the TLWESTDISPATCH, SHAREDTLESTIMATE, and TLDISPATCHCCZ queues. Assigning Private Client MD claims that are not located in ClaimCenter for all other dispatch buckets D out of the CCC1 portal. | N12: Personal | O12: Multi/ Combination | P12: Auto | Q12: All | R12: Back Office | S12: L2 | T12: 2 | U12: 5 | V12: 6 | W12: FTE Based | X12: USD | Y12: 31927.5 | Z12: 16 | AA12: 3 | AB12: 2 | AC12: 3 | AD12: =SUM(Z12:AC12) -> 24 | AE12: =AC12/AD12 -> 0.125 | AK12: 0.9 | AL12: DPU – Defect Per Unit | AO12: Quality methodology | AX12: Onshore clients | AY12: Doc Mgmt | AZ12: Unstructured | BB12: Multiple | BC12: Policyholders, agent, 3rd party | BD12: Dimension 360, Claim center Iron Mountain Connect NY DMV site, DMV spreadsheet Claim Center, Transunion, CBR template Mitchell decision point, Claim Center Mitchell decision point, Claim Center Arbitration forums, productivity sharepoint
A13: Nationwide | B13: Fortune 500 & Large US Insurance carrier | C13: US | D13: Manila, PHP | E13: =VLOOKUP(D13,'Dropdown List'!$F$26:$G$40,2,0) -> Philippines | F13: John Pin Onrade | G13: 1 Year | H13: Active | I13: Claims | J13: Initiation | K13: Claim Setup and assignment | L13: CSP- Orphan mail | TOWRMB | Faxed FNOL Queue | Incoming phone call | Indexing | Mail Upload | Personal line FNOL's Recieved in enewloss email | PL request sent to CCCTECH | Private Client FNOL | Safelite Verification Request Route mails | RSA Towing | Tow Uncashed Checks | Voicemail | Arbiration Tasks | Check Copy Request | Child liens | Claimcenter Unarchived request | Claims Maintenance Services Request | Compex | CSU Pending | Detached claim | Documents on Disabled claim | Litigation images | Litigation Solution | PL Transfer/ Disable | Salvage EFT | Tow Glass Unidentified Mail | Wdclms |W9 Request | M13: Claim services processing receives claims mail documents through ClaimCenter in the Orphan Files. Items are routed from document solutions that are unidentified. Mail is routed as need to the appropriate claim or department. Invoices for Roadside Assistance are received in call center agent and has been set up already requesting to pay the policyholder or vendor. Claims are reviewed for coverage and paid in Claim Center. Auto FNOL(First notices of loss) can originate from AWD. All personal lines auto claims are filed and handled out of the ClaimCenter system. Claims Services processing completes call out to obtain additional information on First Notices of Loss(FNOLs), claim mail, or unidentifiable mail. Associates skilled to specific work types will take inbound calls from agents, members, or providers. AWD captures work electronically and allocates it based on importance, processor skill and processor availability. This page describes the process of identifying the type of work so AWD can allocate work appropriately. Personal Lines Property FNOLs(first notices of loss) originate in AWD. All personal lines property claim are filed and handled out of claim center with the exception of Harleysville. Agents, associates, and third paries send FNOLs and other requests to CCCCTECH All Private Client first notice of loss(FNOL) request received are filed and handled out of CBI(Private Client intake system). This can be located under Aplication in Claims gateway. Claims Serrvices completes coverage verification on Glass Only claims for Nationwide's glass partner, Safelite. Processor also reassign existing claims to Claims Associates for investigation on California car seat claims. Claims Services processing receives claims mail documents through AWD system, various email inboxes, and hard copy mail sent into the processing locations. Mail is routed as needed to the appropriate Claims Associate or Department. Invoices for Roadside Assistance are received in Claim Services via fax, email, or mail and paid to the policyholder or vendor. The claims are set up and paid in Claim Center once the invoice is reviewed and coverage is determined. Activity generates at 180 days to call out the payee to verify if check was received or not. Child Support Lien Network emails the CCCTECH inbox each day, requesting the status of claims. If Claim is archived in ClaimCenter submit request to unarchive | N13: Personal | O13: Multi/ Combination | P13: Auto | Q13: All | R13: Blended | S13: L2 | T13: 2 | U13: 5 | V13: 6 | W13: FTE Based | X13: USD | Y13: 31893.75 | Z13: 9 | AA13: 4 | AB13: 2 | AC13: 13 | AD13: =SUM(Z13:AC13) -> 28 | AE13: =AC13/AD13 -> 0.46428571 | AK13: 0.9 | AL13: DPU – Defect Per Unit | AO13: Quality methodology | AX13: Onshore clients | AY13: FNOL Processing | AZ13: Unstructured | BB13: Multiple | BC13: Policyholders, agent, 3rd party | BD13: Claim center, Gateway, ISO, AWD
A14: Nationwide | B14: Fortune 500 & Large US Insurance carrier | C14: US | D14: Manila, PHP | E14: =VLOOKUP(D14,'Dropdown List'!$F$26:$G$40,2,0) -> Philippines | F14: Cherree Anne Leones | G14: 1 Year | H14: Active | I14: Claims | J14: Initiation | K14: Claim Setup and assignment | L14: Certified Mail | Charge/Credit Coding Changes/ Check Copy Requests | File Copy | File Copy – IME | Hello Packet | Medical Records and Bills Request | Misc Letters (ORM Letters, Prior Medical Records Request, Record Only Letter, Reassignment Letter, Closing Notification, Contact Letter) | Payments/Invoices / Texas Board Fees / Sassupport | Proof of Delivery | Provider Phone Call | Returned checks/stop pay/reissue | TDI DWC Documents | Unmatched Mail Vendor Referral | W-9 Requests / Provider Contact. | M14: Certified Mail can be requested anytime a document needs to be sent certified, this typically occurs with a state form Requests are received from claims associates to make payment code changes on Workers' Compensation related claims. The Changes are caused from either a check being send on a wrong claim, the incorrect amount was paid, or a check was coded incorrectly. Workers' Compensation Claims associates will request various parts of the file to be printed. Documents are then returned to the adjuster or sent to another party, typically Trial Division and/or Outside Counsel, per the request via Box.com New Documents are sent to insured and injured works for new Workers' Compensation claims. Mail, email or fax letters to providers to request bills and/or records for the claim file Create and issue claim center letters for the requesting adjuster "1. Emails come from sassupport daily 2. Invoices must be paid by EOD unless the W9 is missing 3. If payment amount issued by Mitchell is $0.00, still mail EOR to provider without check and notate the claim 4. When issuing Private Client payments, follow up next business day to see if any transactions need to be reapproved" SendPro is a 3rd Party application with DocSolutions, used to obtain tracking numbers and signature cards for document bundles sent out of Claim Center. This process outlines the steps to obtain the necessary information, what to upload in Claim Center, and how to document the claim file. The Expedited Claim handling program is designed to increase claim handling efficiencies for low complexity minor medical claims. The Expedited Claim process allows the claims associate to efficiently move the claim through its life cycle by reducing non-value-added claim contacts and minimizing claim documentation requirements. This results in greater flexibility for the claims tam to apply appropriate amount of time, expertise, and resources to claims with greater severity and/or complexity. Handling payments and account information via email, EFT, digital payments and manual checks. Workers' Compensation team receives a request via email to upload attached documents in Claim Center and inform the adjuster on file for further processing. Requests are received via email to confirm whether the filed claim is within Nationwide's system or its assigned to a Third Party Administrator. Utilization of contracted vendors in making vendor referrals such as social media, surveillance and Medical canvassing, Field Case Management and others Contact providers to get the bills and/or records for the claim file. | N14: Commercial | O14: Multi/ Combination | P14: Commercial | Q14: All | R14: Blended | S14: L2 | T14: 2 | U14: 7 | V14: 4 | W14: FTE Based | X14: USD | Y14: 34115 | Z14: 7 | AA14: 2 | AB14: 1 | AC14: 3 | AD14: =SUM(Z14:AC14) -> 13 | AE14: =AC14/AD14 -> 0.23076923 | AK14: 0.9 | AL14: DPU – Defect Per Unit | AO14: Quality methodology | AX14: Onshore clients | AY14: Workers Compensation | AZ14: Unstructured | BB14: Multiple | BC14: Business, agents, providers | BD14: Claim Center, Genesys, Outlook Mailbox, Fax Link, ISO, Private Client
A15: Nationwide | B15: Fortune 500 & Large US Insurance carrier | C15: US | D15: Manila, PHP | E15: =VLOOKUP(D15,'Dropdown List'!$F$26:$G$40,2,0) -> Philippines | F15: Narissa Dela Rosa | G15: 1 Year | H15: Active | I15: Claims | J15: Initiation | K15: Data entry | L15: Dispatch+Assignments File Claimant Carrier FNOL File Copy/File Request General Admin+Imaging General Admin+Medical Requests ID Admin/Ordering+ClaimCenter Changes ID Admin/Ordering+New Hire Equipment and Access ID Admin/Ordering+Order Supplies/Equipment ID Admin/Ordering+Ordering System Access/IDs ID Admin/Ordering+Terminations General Admin+AIS No Match General Admin+Box General Admin+Child Liens General Admin+Document Uploads General Admin+Escheat General Admin+eSubro Hub General Admin+Inventory Content Lists General Admin+LitFax General Admin+Litigation Solutions General Admin+Medicare General Admin+NWSOP General Admin+Other - General Admin+Record Requests General Admin+Respondant Arbitrations General Admin+SIU Blue | M15: Supplier shall handle various administrative tasks for commercial lines of business, including the assignment of work, managing time-sensitive requests, coordinate data gathering and information, prepare reports, ensure coordination between administrative functions across relevant departments of the Customer, and file first notice of loss (FNOL) with applicable third party carriers. | N15: Commercial | O15: Multi/ Combination | P15: Commercial | Q15: All | R15: Blended | S15: L2 | T15: 2 | U15: 5 | V15: 6 | W15: FTE Based | X15: USD | Y15: 31910.625 | Z15: 8 | AA15: 2 | AB15: 1 | AC15: 3 | AD15: =SUM(Z15:AC15) -> 14 | AE15: =AC15/AD15 -> 0.21428571 | AK15: 0.9 | AL15: DPU – Defect Per Unit | AO15: Quality methodology | AX15: Onshore clients | AY15: Claims Admin | AZ15: Unstructured | BB15: Multiple | BC15: Policyholders, agent, 3rd party | BD15: Outlook, Ariba, EA Sharepoint, MyTech, Service Now, IIQ, Agero, Mozart, DPA, ARMS, Knowledge Advance, EFileNet, Onboarding Guide Excel
A16: Nationwide | B16: Fortune 500 & Large US Insurance carrier | C16: US | D16: Manila, PHP | E16: =VLOOKUP(D16,'Dropdown List'!$F$26:$G$40,2,0) -> Philippines | F16: Narissa Dela Rosa | G16: 1 Year | H16: Active | I16: Claims | J16: Initiation | K16: Claim Setup and assignment | L16: 1099 Correction Bnotice W9 Requests Reject Report - Taxport Tax Returned Mail CL requests sent to CCCCTECH Check copy requests Claims Maintenance Services Requests PL Transfer/Disable CL Transfer/disables NWAG email box AG FNOLs received in enewloss email Commercial Lines FNOLs received in enewloss email Faxed FNOL queue Harleysville CL Requests sent to FNOL Tow Claims/Tow Mail Detached Claims Safelite verification requests - Help Desk AGASSIST Allied Extra CLAIMTAX CSP - Orphan Mail Incoming Phone Call IRS Penalty List - 972CG Mail Upload MailPrep NWAG Claims Operation Queue Salvage EFT Special Project Tow Glass Unidentified Mail Voicemail W9 Entry - via email to associate Wdclms Code Cards for Allied purged policies Tax Levy and UCC Liens | M16: Supplier shall handle a combination of tasks for commercial lines of business such as handling claim resolution, managing intricate claims services functions, handling correspondence, conducting statistical reporting, handling small first_x0002_party claims, assisting with special projects across various business lines of the Customer | N16: Commercial | O16: Multi/ Combination | P16: Commercial | Q16: All | R16: Blended | S16: L2 | T16: 2 | U16: 7 | V16: 7 | W16: FTE Based | X16: USD | Y16: 32855.625 | Z16: 24 | AA16: 2 | AB16: 2 | AC16: 7 | AD16: =SUM(Z16:AC16) -> 35 | AE16: =AC16/AD16 -> 0.2 | AK16: 0.9 | AL16: DPU – Defect Per Unit | AO16: Quality methodology | AX16: Onshore clients | AY16: Claims Processing | AZ16: Unstructured | BB16: Multiple | BC16: Policyholders, agent, 3rd party | BD16: Outlook, Ariba, EA Sharepoint, MyTech, Service Now, IIQ, Agero, Mozart, DPA, ARMS, Knowledge Advance, EFileNet, Onboarding Guide Excel
A17: Nationwide | B17: Fortune 500 & Large US Insurance carrier | C17: US | D17: Manila, PHP | E17: =VLOOKUP(D17,'Dropdown List'!$F$26:$G$40,2,0) -> Philippines | F17: Narissa Dela Rosa | G17: 1 Year | H17: Active | I17: Claims | J17: Initiation | K17: Claim Setup and assignment | L17: Keying Processing: Agent/Foreign Wire Transfers Keying Processing: Multiple & Bulk Invoices – Emails Keying Processing: ODEI Invoices to Pay Keying Processing: Stale Dated/Stop Pays Keying Processing: Transfers/Recodes Keying Processing: Invoices – Emails / Omniview Vendor Processing: Link & Sync Vendor Processing: New Vendor Setup with W9 Vendor Processing: PIP New Vendor Setup Vendor Processing: Scheduler – ClaimCenter Vendor Processing: Scheduler – Omniview Vendor Processing: THF New Vendor Setup Vendor Processing: Vendor Updates Vendor Processing: W9 Repository | M17: Supplier shall provide check processing services which involves handling time sensitive requests, vendor processing tasks, claims invoice tasks, payment tasks and single invoices that come in via email or Omniview that need paid to be paid to third party vendors. | N17: Commercial | O17: Multi/ Combination | P17: Commercial | Q17: All | R17: Blended | S17: L2 | T17: 2 | U17: 5 | V17: 3 | W17: FTE Based | X17: USD | Y17: 34391.25 | Z17: 6 | AA17: 2 | AB17: 1 | AC17: 2 | AD17: =SUM(Z17:AC17) -> 11 | AE17: =AC17/AD17 -> 0.18181818 | AK17: 0.985 | AL17: Weighted DPO – Weighted Defect Per Opportunity | AO17: Quality methodology | AX17: Onshore clients | AY17: Claims Processing | AZ17: Unstructured | BB17: Multiple | BC17: Policyholders, agent, 3rd party | BD17: Claim center, Gateway, ISO, AWD
A18: Nationwide | B18: Fortune 500 & Large US Insurance carrier | C18: US | D18: Manila, PHP | E18: =VLOOKUP(D18,'Dropdown List'!$F$26:$G$40,2,0) -> Philippines | F18: Narissa Dela Rosa | G18: 1 Year | H18: Active | I18: Claims | J18: Initiation | K18: Data entry | L18: First Notice of Loss: ESS emails and eFaxes First-Notice-Of-Loss: ESS Special programs and Western Heritage: Emails & eFaxes First-Notice-Of-Loss: Incoming inquiry and FNOL Calls (Phones - CSR) NW E&S FNOL & Inquiry Calls (Previously in Todd Robertson's org) ClaimCenter Research | M18: Supplier shall handle back-office services include managing FNOL emails (essreportaloss@nationwide.com), eFaxes and emails for the ESS program business and small volume of Western Heritage business. Supplier will also manage FNOL emails (essreportaloss@nationwide.com) and faxes that are ingested into Omniview. | N18: Commercial | O18: Multi/ Combination | P18: Commercial | Q18: All | R18: Blended | S18: L2 | T18: 2 | U18: 14 | V18: 8 | W18: FTE Based | X18: USD | Y18: 32855.625 | Z18: 9 | AA18: 2 | AB18: 1 | AC18: 3 | AD18: =SUM(Z18:AC18) -> 15 | AE18: =AC18/AD18 -> 0.2 | AK18: 0.95 | AL18: Weighted DPO – Weighted Defect Per Opportunity | AO18: Quality methodology | AX18: Onshore clients | AY18: Claims Support: ESS New Loss Back Office | AZ18: Unstructured | BB18: Multiple | BC18: Policyholders, agent, 3rd party | BD18: Claim center, Gateway, ISO, AWD
A19: American Modern Insurance Group | B19: US National Specialty Carrier | C19: US | D19: Noida, India | E19: =VLOOKUP(D19,'Dropdown List'!$F$26:$G$40,2,0) -> India | F19: Souvick Paul | G19: 5 | H19: Active | I19: Underwriting and UW Support | J19: Broker and Agent Management | K19: New Agent Set-up | L19: Coordination Setup Modification Cancellations | M19: Coordination process involves reviewing and coordinating the requests received in Appian with respect to making changes to agency, licensed producer, Sub-producer, Direct employee and other entity details. Setup and Modifications process involve either working on the setup (appointing new agenies/agents) requests or changes to existing entities requests in Prism (Modern Link) based on the SOP guidelines as well as information available in Vertafore application. Cancels process involves managing termination request for entities such as sub/licensed producer, DE/Processor, products and states in Prism (Modern Link) based on the SOP guidelines as well as information available in Vertafore, Cognos reports and HUON application | N19: Specialty | O19: Multi/ Combination | P19: Auto, Home, Motor Cycle, Collector Vehicle, Watercraft, Manufactured/Mobile home | Q19: Small & Mid Size | R19: Back Office | S19: L3 | T19: 1 | U19: 8 | V19: 8 | W19: FTE Based | X19: USD | Y19: 29825.983 | Z19: 17 | AA19: 2 | AB19: 1 | AC19: 2 | AD19: =SUM(Z19:AC19) -> 22 | AE19: =AC19/AD19 -> 0.090909091 | AF19: 21000 | AG19: NA | AH19: Mar, Apr, May & Jun | AI19: 20 | AJ19: Same Day | AK19: 0.96 | AL19: DPO – Defect Per Opportunity | AM19: NA | AN19: NA | AO19: Agency feedbacks | AP19: Quality | AQ19: NA | AR19: NA | AS19: NA | AT19: NA | AU19: NA | AV19: NA | AW19: Appian for workflow management. Scout for sched aderence monitoring | AX19: Agencies & inhouse team | AY19: Multiple | AZ19: Semi-Structured | BA19: Emails: 10% Database: 90% | BB19: Emails | BC19: Agencies | BD19: Citrix Appian Modern Link AMSuite Filenet Outlook Vertafore DocuSign Cognos Adobe Pro Access Accessory Manager Blue Screens AMIG Shared Drive MS EXCEL MS Teams MS Word
A20: American Modern Insurance Group | B20: US National Specialty Carrier | C20: US | D20: Noida, India | E20: =VLOOKUP(D20,'Dropdown List'!$F$26:$G$40,2,0) -> India | F20: Souvick Paul | G20: 5 | H20: Active | I20: Underwriting and UW Support | J20: Policy Servicing | K20: Endorsements intake and setup | L20: Non Premium Endorsement, Premium Bearing Endorsement, AOR, Schedule Manufactured Home, Cancellation, AOR, Watercraft Processing, Motorcycle processing, Collector vehicle processing, EZPAY, e-Sign, New Business, DocuSign | M20: Cases are received in form of emails/ Modernlink/ Filenet/ Phonechat/ manual requests in Appian from agent/insured/ third parties in regards to their Insurance products with AMIG. Requests are in regards to updating policies/ billing or coverage inquiries which may or may not result in impacting the premiums. The general steps include verifying the requestor’s authenticity, taking appropriate actions which includes policy processing in Amsuite/ Modernlink, sending response to requestor on what all actions are completed basis the request or if there are any further requirements to complete the request and imaging the requests/ attachments in Amsuite/Filenet. Post all the steps memo is created which includes documenting all the necessary details pertaining to the case. | N20: Specialty | O20: Multi/ Combination | P20: Auto, Home, Motor Cycle, Collector Vehicle, Watercraft, Manufactured/Mobile home | Q20: Small & Mid Size | R20: Back Office | S20: L3 | T20: 1 | U20: 4 | V20: 6 | W20: FTE Based | X20: USD | Y20: 29825.983 | Z20: 27 | AA20: 2 | AB20: 1 | AC20: 3 | AD20: =SUM(Z20:AC20) -> 33 | AE20: =AC20/AD20 -> 0.090909091 | AF20: 25000 | AG20: NA | AH20: Mar, Apr, May & Jun | AI20: 9 | AJ20: 1 Day | AK20: 0.92 | AL20: DPO – Defect Per Opportunity | AM20: NA | AN20: NA | AO20: Customer feedbacks | AP20: Quality | AQ20: NA | AR20: NA | AS20: NA | AT20: NA | AU20: NA | AV20: NA | AW20: Appian for workflow management. Scout for sched aderence monitoring | AX20: Agent, Insured, Third Parties & inhouse team | AY20: Multiple | AZ20: Unstructured | BA20: Emails: 90% Images: 10% | BB20: Emails | BC20: Agents, Insureds & Third parties | BD20: Citrix Appian Modern Link AMSuite Filenet Outlook DocuSign Adobe Pro Access MAT Tool AMIG Shared Drive MS EXCEL MS Teams MS Word
A21: American Modern Insurance Group | B21: US National Specialty Carrier | C21: US | D21: Noida, India | E21: =VLOOKUP(D21,'Dropdown List'!$F$26:$G$40,2,0) -> India | F21: Souvick Paul | G21: 5 | H21: Active | I21: Underwriting and UW Support | J21: Policy Servicing | K21: Indexing | L21: Cordination to Underwriting | M21: This process includes reviewing and coordinating requests received in Appian. Requests/emails received in Appian must be reviewed and identified the request per the nature. After the selection of type, request to be coordinated to appropriate team (underwriting/Not assigned bucket/Customer Service, others) for Residential & Recreational LOB as outlined in the SOP. For Certified policy request task, we have to Certify the dec page and validate form numbers from the guidewire accordingly, 100% volume to be touched by EXL & worked upon as outlined in SOP. In the Commercial line section, we review the requests/emails (received in endorsement & NB requests mailboxes) and setup the task in the task manager and coordinate to appropriate underwriters. | N21: Specialty | O21: Multi/ Combination | P21: Auto, Home, Motor Cycle, Collector Vehicle, Watercraft, Manufactured/Mobile home | Q21: Small & Mid Size | R21: Back Office | S21: L3 | T21: 1 | U21: 2 | V21: 2 | W21: FTE Based | X21: USD | Y21: 29825.983 | Z21: 7 | AA21: 0 | AB21: 0.5 | AC21: 1 | AD21: =SUM(Z21:AC21) -> 8.5 | AE21: =AC21/AD21 -> 0.11764706 | AF21: 7000 | AG21: NA | AH21: Mar, Apr, May & Jun | AI21: 5 | AJ21: Same Day | AK21: 0.9 | AL21: DPO – Defect Per Opportunity | AM21: NA | AN21: NA | AO21: NA | AP21: NA | AQ21: NA | AR21: NA | AS21: NA | AT21: NA | AU21: NA | AV21: NA | AW21: Appian for workflow management. Scout for sched aderence monitoring | AX21: Agent, Insured & inhouse team | AY21: Multiple | AZ21: Unstructured | BA21: Emails: 98% Application on browser: 1% Mainframe: 1% | BB21: Emails | BC21: Underwriters | BD21: Citrix Appian Modern Link AMSuite Filenet Outlook Adobe Pro Access AMIG Shared Drive MS EXCEL MS Teams MS Word
A22: American Modern Insurance Group | B22: US National Specialty Carrier | C22: US | D22: Noida, India | E22: =VLOOKUP(D22,'Dropdown List'!$F$26:$G$40,2,0) -> India | F22: Souvick Paul | G22: 2.9 | H22: Active | I22: Claims | J22: Investigation | K22: Requesting Police report | L22: Claims FileNet, File Copy, Police/Fire Report, Recorded Statement, NSM, MBA Commercial, SerachTec deed search, ISO Deed Search & New Losses | M22: The claims transactions involve uploading emails, saving the documents for adjuster in file copy request, pull the Dec Page to certify for certify policy request, order the PR/FR reports through ISO in PR/FR task, submit the recorded statement on 3rd party website for transcription and new claims are being generated on the guidewire basis the loss details received on email for the task NSM, MBA commercial & New losses. | N22: Specialty | O22: Multi/ Combination | P22: Auto, Home, Motor Cycle, Collector Vehicle, Watercraft, Manufactured/Mobile home | Q22: Small & Mid Size | R22: Back Office | S22: L3 | T22: 1 | U22: 3 | V22: 3 | W22: FTE Based | X22: USD | Y22: 28113.85 | Z22: 4 | AA22: 0 | AB22: 0.5 | AC22: 1 | AD22: =SUM(Z22:AC22) -> 5.5 | AE22: =AC22/AD22 -> 0.18181818 | AF22: 12000 | AG22: NA | AH22: Mar & Oct | AI22: 3 | AJ22: Same Day | AK22: 0.9 | AL22: DPO – Defect Per Opportunity | AM22: NA | AN22: NA | AO22: NA | AP22: NA | AQ22: NA | AR22: NA | AS22: NA | AT22: NA | AU22: NA | AV22: NA | AW22: No | AX22: Adjuster & inhouse team | AY22: Multiple | AZ22: Unstructured | BA22: Emails: 80% Application on browser: 20% | BB22: Emails | BC22: Underwriters | BD22: Citrix Modern Link AMSuite Filenet Outlook Production tool Adobe Pro Access MS Access Tool ISO Guidewire Claims Center Infraware SerachTEc Fonefinder AMIGAddin.Amclaims tool AMIG Shared Drive MS EXCEL MS Teams MS Word
A23: RSA Insurance | B23: UK P&C client | C23: UK | D23: Pune, India | E23: =VLOOKUP(D23,'Dropdown List'!$F$26:$G$40,2,0) -> India | F23: Kanishka Singh | G23: 1 | H23: Active | I23: Underwriting and UW Support | J23: Broker and Agent Management | K23: Maintenance | L23: BRM Support Application Management Change/testing Coordination Data Monitoring Application Support Data Reporting | M23: Identify opportunities and manage trends: Use BRM to spot business opportunities and trends. Plan broker strategies: Utilize the application to support strategic planning for brokers. Allocate policy activities: Assign policy-related tasks requested by brokers and customers. Perform periodic policy services: Carry out regular services on policies. Manage broker relationships: Proactively manage broker interactions and relationships. Enable seamless workflow management: Handle leads, quotes, mid-term adjustments, and renewals efficiently. | N23: Commercial | O23: Multi/ Combination | P23: Auto,Property,Package | Q23: All | R23: Back Office | S23: L5 | T23: 1 weeks | U23: 4 weeks | V23: 2 weeks | W23: FTE Based | X23: GBP | Y23: 25059 | Z23: 2 | AA23: 0 | AB23: 1 | AC23: 0 | AD23: =SUM(Z23:AC23) -> 3 | AE23: =AC23/AD23 -> 0 | AF23: NA | AG23: NA | AH23: NA | AI23: NA | AJ23: NA | AK23: NA | AL23: Others | AM23: NA | AN23: NA | AO23: NA | AP23: NA | AQ23: NA | AR23: NA | AS23: NA | AT23: NA | AU23: NA | AV23: NA | AW23: NA | AX23: Internal departments Brokers Onshore Underwriters | AY23: Information, forms, policy details, customer requests, database entries, and broker strategies | AZ23: Unstructured | BA23: Emails: 60% Spreadsheets: 20% System-Generated Reports: 10% Broker Correspondence: 10% | BB23: Reports, strategic plans, task assignments, service records, Digital reports, dashboards, emails, notifications, and workflow updates | BC23: Onshore Underwriters Internal Teams | BD23: Broker Relationship Management (BRM) systems
A24: RSA Insurance | B24: UK P&C client | C24: UK | D24: Noida, India | E24: =VLOOKUP(D24,'Dropdown List'!$F$26:$G$40,2,0) -> India | F24: Kanishka Singh | G24: 1 | H24: Active | I24: Underwriting and UW Support | J24: Information Gathering and Risk Selection | K24: Broker Correspondence | L24: System-Generated Reports (HUB) Management Scanned Correspondence Handling (SRI) Policy Rekeying Report Management Diary Reminder Management Geo Score Generation and Provision Policy Actions and Leads Creation RNL Declarations Dispatch to Brokers New Policy Setup via Rekeying Motor Cover Notes Upload (SRI) | M24: Handle policy rekeying details: Process details from the shared mailbox and HUB broker platform. Manage diary reminders: Handle reminders from BRM. Manage scanned correspondence: Handle correspondence received from brokers, for PA, lead or Indexising. Process periodic spreadsheets: Manage spreadsheets from onshore stakeholders. Handle Motor cover note work: Process work received on the Motor cover note system. Create logs in BRM: Identify requests as new business or changes to existing customer details. Chase required information: Follow up with brokers for necessary information. Rekey policies: Update policies received from brokers. Correspond with brokers: Communicate regarding RNL declarations. Provide Geo scores: Send Geo scores to underwriters on SRI. Upload Motor cover notes: Upload Motor cover notes on SRI. | N24: Commercial | O24: Multi/ Combination | P24: Auto,Property,Package | Q24: All | R24: Back Office | S24: L3 | T24: 1 weeks | U24: 0 | V24: 4 weeks | W24: FTE Based | X24: GBP | Y24: 20183.24 | Z24: 28 | AA24: 2 | AB24: 1 | AC24: 2.5 | AD24: =SUM(Z24:AC24) -> 33.5 | AE24: =AC24/AD24 -> 0.074626866 | AF24: 29303 | AG24: NA | AH24: July, September, October | AI24: Maximum - 120 min, Minimum - 30 sec | AJ24: 0.95 | AK24: 0.95 | AL24: DPU and DPO | AM24: NA | AN24: NA | AO24: NA | AP24: NA | AQ24: NA | AR24: NA | AS24: NA | AT24: NA | AU24: NA | AV24: NA | AW24: NA | AX24: Onshore teams Brokers | AY24: Shared mailbox HUB broker platform BRM diary reminders Scanned correspondence Periodic spreadsheets Motor cover note system | AZ24: Unstructured | BA24: Emails: 60% Spreadsheets: 20% System-Generated Reports: 10% Broker Correspondence: 5% Policy Adjustment Requests: 3% Renewal Requests: 2% | BB24: Policy actions and leads Geo scores Notepad updates | BC24: Underwriters Brokers | BD24: IS2000: For managing policies and generating documents. Acturis: For making underwriting decisions and generating quotes. SRI & IS2000: For handling broker correspondence and policy changes. SRI - Document Management System: For storing and retrieving scanned documents and emails. BRM - Broker Relationship manager software application used to manage workflow across teams
A25: RSA Insurance | B25: UK P&C client | C25: UK | D25: Pune, India | E25: =VLOOKUP(D25,'Dropdown List'!$F$26:$G$40,2,0) -> India | F25: Kanishka Singh | G25: 1 | H25: Active | I25: Underwriting and UW Support | J25: Information Gathering and Risk Selection | K25: Broker Correspondence | L25: System-Generated Reports (HUB) Management Scanned Correspondence Handling (SRI) Policy Rekeying Report Management Diary Reminder Management Geo Score Generation and Provision Policy Actions and Leads Creation RNL Declarations Dispatch to Brokers New Policy Setup via Rekeying Motor Cover Notes Upload (SRI) | M25: Handle policy rekeying details: Process details from the shared mailbox and HUB broker platform. Manage diary reminders: Handle reminders from BRM. Manage scanned correspondence: Handle correspondence received from brokers, for PA, lead or Indexising. Process periodic spreadsheets: Manage spreadsheets from onshore stakeholders. Handle Motor cover note work: Process work received on the Motor cover note system. Create logs in BRM: Identify requests as new business or changes to existing customer details. Chase required information: Follow up with brokers for necessary information. Rekey policies: Update policies received from brokers. Correspond with brokers: Communicate regarding RNL declarations. Provide Geo scores: Send Geo scores to underwriters on SRI. Upload Motor cover notes: Upload Motor cover notes on SRI. | N25: Commercial | O25: Multi/ Combination | P25: Auto,Property,Package | Q25: All | R25: Back Office | S25: L3 | T25: 1 weeks | U25: 0 | V25: 4 weeks | W25: FTE Based | X25: GBP | Y25: 20183.24 | Z25: 28 | AA25: 2 | AB25: 1 | AC25: 2.5 | AD25: =SUM(Z25:AC25) -> 33.5 | AE25: =AC25/AD25 -> 0.074626866 | AF25: 29303 | AG25: NA | AH25: July, September, October | AI25: Maximum - 120 min, Minimum - 30 sec | AJ25: 0.95 | AK25: 0.95 | AL25: DPU and DPO | AM25: NA | AN25: NA | AO25: NA | AP25: NA | AQ25: NA | AR25: NA | AS25: NA | AT25: NA | AU25: NA | AV25: NA | AW25: NA | AX25: Onshore teams Brokers | AY25: Shared mailbox HUB broker platform BRM diary reminders Scanned correspondence Periodic spreadsheets Motor cover note system | AZ25: Unstructured | BA25: Emails: 60% Spreadsheets: 20% System-Generated Reports: 10% Broker Correspondence: 5% Policy Adjustment Requests: 3% Renewal Requests: 2% | BB25: Policy actions and leads Geo scores Notepad updates | BC25: Underwriters Brokers | BD25: IS2000: For managing policies and generating documents. Acturis: For making underwriting decisions and generating quotes. SRI & IS2000: For handling broker correspondence and policy changes. SRI - Document Management System: For storing and retrieving scanned documents and emails. BRM - Broker Relationship manager software application used to manage workflow across teams
