Workbook
Name Audit_ATC: 'Reference Tab - Do not Delete'!$I$21:$I$27
Name BIE: 'Reference Tab - Do not Delete'!$G$21:$G$27
Name DT_WC: 'Reference Tab - Do not Delete'!$D$21:$D$27
Name E_E2E: 'Reference Tab - Do not Delete'!$F$21:$F$27
Name Fin_Auto: 'Reference Tab - Do not Delete'!$K$21:$K$27
Name FNOL: 'Reference Tab - Do not Delete'!$B$21:$B$27
Name Food: 'Reference Tab - Do not Delete'!$A$21:$A$31
Name Int_Col: 'Reference Tab - Do not Delete'!$H$21:$H$27
Name Life_Cycle: 'Reference Tab - Do not Delete'!$C$35:$C$42
Name NB_PaaS: 'Reference Tab - Do not Delete'!$E$21:$E$27
Name PaaS: 'Reference Tab - Do not Delete'!$C$21:$C$27
Name PRA: 'Reference Tab - Do not Delete'!$J$21:$J$27
Name Sign_Off___Next_Steps: 'Reference Tab - Do not Delete'!$B$35:$B$40
Name TrRFF: 'Reference Tab - Do not Delete'!$L$21:$L$27
Name VOC_Source: 'Reference Tab - Do not Delete'!$A$35:$A$40

Sheet Sheet3
A1: Client | B1: Geography | C1: Strategic/Named | D1: Client Exec | E1: CEO | F1: CFO | G1: CRO | H1: CCO | I1: COO | J1: CIO/CTO | K1: CUO | L1: GWP | M1: Growth % | N1: Combined Ratio (2019) | O1: Do they outsource today | P1: Competitors | Q1: Renewal Date
A2: Swiss Re | B2: US | C2: Named | D2: Mohit | E2: J.Eric Smith | F2: Brian Rosenblum | G2: Stefanie Stratos | H2: Thomas Hyatte | I2: Rich Agar | J2: Prashanthi Roy /Pravina Ladva | L2: $42,228M | M2: 0.029 | N2: 1.0708 | O2: Yes | P2: CSC, Genpact, TCS | Q2: 2021 (They have multiple BPO, automation and analytics partner)
A3: Nationwide Insurance | B3: US | C3: Named | D3: Mohit | E3: Kirt Walker | F3: Mark Thresher | G3: Klaus Diem | H3: Sandra Rich | I3: Mark Berven | J3: James Fowler | L3: $49.3B | M3: 0.025 | N3: 0.94 | O3: Yes | P3: Cognizant, Genpact | Q3: Mid 2021, 2022
A4: American Modern | B4: US | C4: Named | D4: Sean | E4: Andreas Kleiner | F4: Rene Gobanya | G4: Trey Griffith | H4: Eric Hunzinger | I4: Paul Schneider | J4: Bill Gottsacker | K4: Kam Jha | L4: $2.5B | M4: 0.03 | N4: N/A | O4: Yes | P4: TCS | Q4: Just signed with us
A5: Everest Insurance | B5: US | C5: Named | D5: Sean | E5: Mike Karmilowicz | F5: Dana Lodge | G5: Bill Thygeson, CAO | H5: Patricia Mcmahon | I5: Mike Mulray | J5: Owen Williams | K5: Open | L5: $4B | M5: 0.04 | N5: 88.7 | O5: Yes | P5: None | Q5: 2023
A6: Axis | B6: US | C6: Named | D6: Sean | E6: Albert Benchimol | F6: Pete Vogt | G6: Ben Rubin | H6: Mike Baumel | I6: Rob Hartman | J6: Keith Schlosser | K6: Eric Gesick | L6: 6.9 | M6: 0.01 | N6: 107.3 | O6: Yes | P6: Genpact, Infy | Q6: 2022
A7: IAG | B7: Australia | C7: Strategic | D7: Vilas | E7: Peter Harmer | F7: Nick Hawkins | G7: David Watts | J7: Neil Morgan | L7: 12,135 ($m) | M7: 0.011 | N7: 1.23 | O7: Yes | P7: WNS | Q7: 44470
A8: Suncorp | B8: Australia | C8: Strategic | D8: Vilas | E8: Steve Johnston | F8: Jeremy Robson | G8: Fiona Thompson | I8: Paul Smeaton (Insurance) | J8: Adam Bennett | L8: 8119 ($m) | M8: 0.015 | N8: 0.96 | O8: Yes | P8: WNS, Genpact, Cognizant | Q8: 44191
A9: Allstate | B9: US | C9: Strategic | D9: Amit Gaba | E9: Tom Wilson | F9: Mario Rizzo | G9: Mark Prindiville | H9: Eric Brandt | I9: Glenn Shapiro | J9: Suren Gupta | L9: $34.8B | M9: 0.057 | N9: 85 | O9: Yes | P9: Genpact, Fractal | Q9: MSA is perpetual
A10: Kemper | B10: US | C10: Other | D10: Amit Gaba | E10: Joe Lacher | F10: Jim McKinney | G10: Max Mindak | H10: Kim Leggette | I10: Duane Sanders | J10: Charles Brooks | L10: $4B | M10: 0.3 | N10: 93 | O10: Yes | P10: Accenture | Q10: Key SOW renewal date Jan 1, 2021
A11: Travelers | B11: US | C11: Named | D11: Sean | E11: Alan Schnitzer | F11: Dan Frey | G11: Bruce Jones | H11: Nicolas Seminara | I11: Mojgan Lefebvre | J11: Mojgan Lefebvre | K11: Rick Schug | L11: $29B | M11: 0.05 | N11: 96.5 | O11: Yes | P11: CTS, WNS, Genpact | Q11: 2021
A12: Great American | B12: US | C12: Named | D12: Sean | E12: Carl Lindnor, Craig Lindnor | F12: Jeff Consolino | I12: Gary Gruber | J12: Chad Stewart | L12: $13B | M12: 0.02 | N12: 93.7
A13: Munich Re | B13: US | C13: Named | D13: Mohit | E13: Dave Brune | F13: Oliver J. Horbelt/Angela Homm | G13: Catherine Smith | H13: JannaLyn Allen | I13: Anita Kuchma | J13: Phil Roeper | L13: $60,433M | M13: 0.02 | N13: 1.01 | O13: Yes | P13: Wipro,Capgemini | Q13: Sep, 2022 (with Wipro) and 23rd July 2020 with Capgemini
A14: State Farm | B14: US | C14: Named | D14: Mohit | E14: Bruce Hull | F14: Connie Storey | G14: Cathy Wallace | H14: Terrence Ludwig | I14: Cleo Villaflores | J14: Ashley Pettit | L14: $42,137M | M14: 0 | N14: 0.987 | O14: No | P14: Wipro | Q14: NA
A15: Mapfre | B15: US | C15: Named | D15: Mohit | E15: Alexis Sanchez Geigel | F15: Francois Facon | G15: Dana Whiteley | H15: Christopher Matherly | I15: Scott Hammond | J15: Gregg Nickerson | L15: $6,398.6M | M15: 0.031 | N15: 0.976 | O15: Yes | P15: WNS | Q15: NA

Sheet Home
B1: P&C Solutions and Go-To-Market Strategy
K24: Version 1.5 | L24: Last Updated | N24: 44046

Sheet Go-To-Market Plan
B2: Home
B4: P&C Go-To-Market Business Development Plan
B6: Reset, Refresh and Re-imagine P&C business, pivoting to a solutions based, sustainable growth focused organization
B8: A. | C8: Critical success factors for EXL P&C
C9: Goal: Global Brand, Best in the Industry
C10: How: Global Market Share - ~20% CAGR; Growth Focus - $500M Annual Revenue; Industry Recognition -Thought Leader, Digital Disruptor
C11: Change needed: Focus on Industry Solutions, Customer Outcomes, Speed to Market, Augment with the Best Talent
C13: We are pivoting to be the Preferred Digital Transformation partner for the industry. EXL P&C a ‘solutions organization’ vs. a ‘services organization’
B15: B. | C15: What are clients telling us
C16: Clear appetite for digital solutions (vs. platforms) as a service (AI at the leading edge)
C17: Identify Problems and come with solutions…will buy solutions not people (People are only part of the solution – typically a combination of people and digital)
C18: Templatize transformation at base level…solve more end to end (Transformation benefit is table stakes)
C19: Price on solutions…vs. individual components (but need to be able to modularize the offerings as well)
C20: Develop transparent view from an end customer perspective, customer journeys…single view of customer (truly enable decisions with data and analytics)
C21: Lead the market; don’t chase it (we are often late to the party)
B23: C. | C23: Approach and Steps towards developing a solutions based go-to-market plan
C24: We believe there is a lot of great opportunities within the following layers as we cast a broad net and pivot towards solution based, sustainable growth focused organization-
C26: Tier 1: Strategic Accounts - expand to sell solutions vs. FTE; partner to co-build solutions with anchor clients; personalized CxO specific campaigns with solutions mapped to strategic priorities
C27: Tier 2: Named Accounts - research top 3-5 priorities, cross reference solution ideas with priorities; P&C solution owners to map with each account and Exec, personalized account based marketing
C28: Tier 3: Expand the net to include mid-level, regional, specialty, reinsurance carriers, brokers and smaller size firms, beyond the traditional big carriers. Research priorities, map solutions and GTM
C29: Tier 4: Target Competition logos - go after upcoming renewals (e.g. Project Ocean); research logos with performance dis-sat/evolving priorities (e.g.. Aon); pitch Digital and Data in BPO only clients etc.
C31: Step 1: Shortlist top-30 P&C firms across the globe (mix of Carriers, brokers, across above Tiers), add analysis on key metrics like NWP, Combined Ratio, Competition, Sourcing, Share of Wallet, Partner Network etc.
C32: Step 2: Map key CxOs across these top-30 firms
C33: Step 3: Research on top 3-5 priorities across the shortlisted firms
C34: Step 4: Cross-reference solution ideas with strategic priorities for solution build and logo prioritization
C35: Step 5: Allocate each logo and CxOs to P&C frontend team (AM, CE, Growth Leader, Sales) based on P&C solution teams
C36: Step 6: Map GTM ideas like ABM, Infographics, Webinars, Influencer Events, Case Studies and Webinars for Top-30 logos
C37: Step 7: Develop prioritization roadmap over next 12-18 months, with 30-60-90 day sprints
C38: Step 8: SFDC driven reviews and cadence
B40: D. | C40: Displacing competition and building for continuous, sustainable growth
C42: Proactively identifying white spaces across our capability set to develop a Build/Buy/Partner combination strategy around
C43: Insuretechs : few firms stand out to close our current capability gaps – Shift Technology, CapeAnalytics, Snapsheet, Datacubes etc. Analyzing from a list of 80 firms
C44: TPAs for onshore capabilities in response to market demand – e.g. Crawford Broadpsire, Gallagher Bassett, Segewick, York
C45: Competition analysis – to go after logos we don’t work with and assess partnerships / acquisitions that our competition has made
C46: Performing capability gap analysis : outside-in, inside-out
B48: E. | C48: Proactively developing ‘packaged solutions’ in response to outside-in industry problems, with an anchor client across each ‘solution’
B50: 1 | C50: FNOL as-as-service
B51: 2 | C51: Payments-as-a Service
B52: 3 | C52: Digitally Transforming Workers’ Compensation Claims
B53: 4 | C53: Digitally Transforming Commercial Underwriting
...

Sheet Top Insurers and Brokers
A1: Global List of Top Insurers & Brokers
A3: The following table comprises of Top Insurers and Brokers rated per industry standards. This list will be used to map Client Prioritization and Future GTM Strategies. This list includes non-EXL clients as well
A5: Home | B5: Source: | C5: http://www.ambest.com/review/displaychart.aspx?Record_Code=274586 | J5: https://www.insurancejournal.com/top-100-insurance-agencies/ | AI5: Inputs - Vishal Gupta | AK5: Inputs - CE
A6: Growth Leader | B6: Company/ Group | C6: CID | D6: Type | E6: NWP - 2019 | F6: % Change | G6: 2018 Rank | H6: 2019 Rank | I6: Geography | J6: Combined Ratio - 2019 | K6: Relationship Type | L6: CE | M6: CEO | N6: CFO | O6: CRO | P6: CCO | Q6: COO | R6: CIO/CTO | S6: CUO | T6: Outsource | U6: EXL Competitors | V6: Renewal Date | W6: InsureTech Partner 1 | X6: InsureTech Partner 2 | Y6: InsureTech Partner 3 | Z6: InsureTech Partner 4 | AA6: InsureTech Partner 5 | AB6: TPA Partner 1 | AC6: TPA Partner 2 | AD6: TPA Partner 3 | AE6: TPA Partner 4 | AF6: TPA Partner 5 | AG6: NWP-Range | AH6: Ranking Range | AI6: EXL Client | AJ6: 2020-Rev Budget | AK6: EXL's Share of Wallet | AL6: Competition Account | AM6: Competition's Share of Wallet | AN6: Relationship Maturity (Yrs) | AO6: Renewal Timeframe | AP6: Future TCV Potential | AQ6: Client Priority Rating
A7: Mohit | B7: State Farm Group | C7: 1 | D7: Carrier | E7: 65100455000 | F7: =-0.6/100 -> -0.006 | G7: 1 | H7: 1 | I7: US | J7: 98.7 | K7: Named | L7: Mohit | M7: Bruce Hull | N7: Connie Storey | O7: Cathy Wallace | P7: Terrence Ludwig | Q7: Cleo Villaflores | R7: Ashley Pettit | T7: Yes | U7: Wipro | W7: ITP1 | AG7: =IF(E7="","",IF(E7>='Reference Tab - Do not Delete'!$E$35,'Reference Tab - Do not Delete'!$D$35,IF(AND(E7>='Reference Tab - Do not Delete'!$E$36,E7<'Reference Tab - Do not Delete'!$E$35),'Reference Tab - Do not Delete'!$D$36,IF(AND(E7>='Reference Tab - Do not Delete'!$E$37,E7<'Reference Tab - Do not Delete'!$E$36),'Reference Tab - Do not Delete'!$D$37,IF(AND(E7>='Reference Tab - Do not Delete'!$E$38,E7<'Reference Tab - Do not Delete'!$E$37),'Reference Tab - Do not Delete'!$D$38,'Reference Tab - Do not Delete'!$D$39))))) -> Above $50B | AH7: =IF(H7="","DNA",IF(H7<=10,"Top 10",IF(AND(H7<=25,H7>10),"11 - 25",IF(AND(H7<=50,H7>25),"26 - 50","Above 50")))) -> Top 10 | AI7: =IF(AJ7>0,"Yes","") | AJ7: 0
B8: Berkshire Hathaway Ins | C8: 2 | D8: Carrier | E8: 53754763000 | F8: 0.079 | G8: 2 | H8: 2 | I8: US | W8: ITP2 | AG8: =IF(E8="","",IF(E8>='Reference Tab - Do not Delete'!$E$35,'Reference Tab - Do not Delete'!$D$35,IF(AND(E8>='Reference Tab - Do not Delete'!$E$36,E8<'Reference Tab - Do not Delete'!$E$35),'Reference Tab - Do not Delete'!$D$36,IF(AND(E8>='Reference Tab - Do not Delete'!$E$37,E8<'Reference Tab - Do not Delete'!$E$36),'Reference Tab - Do not Delete'!$D$37,IF(AND(E8>='Reference Tab - Do not Delete'!$E$38,E8<'Reference Tab - Do not Delete'!$E$37),'Reference Tab - Do not Delete'!$D$38,'Reference Tab - Do not Delete'!$D$39))))) -> Above $50B | AH8: =IF(H8="","DNA",IF(H8<=10,"Top 10",IF(AND(H8<=25,H8>10),"11 - 25",IF(AND(H8<=50,H8>25),"26 - 50","Above 50")))) -> Top 10 | AI8: =IF(AJ8>0,"Yes","") | AJ8: 0
B9: Progressive Ins Group | C9: 3 | D9: Carrier | E9: 37578689000 | F9: 0.152 | G9: 3 | H9: 3 | I9: US | W9: ITP3 | AG9: =IF(E9="","",IF(E9>='Reference Tab - Do not Delete'!$E$35,'Reference Tab - Do not Delete'!$D$35,IF(AND(E9>='Reference Tab - Do not Delete'!$E$36,E9<'Reference Tab - Do not Delete'!$E$35),'Reference Tab - Do not Delete'!$D$36,IF(AND(E9>='Reference Tab - Do not Delete'!$E$37,E9<'Reference Tab - Do not Delete'!$E$36),'Reference Tab - Do not Delete'!$D$37,IF(AND(E9>='Reference Tab - Do not Delete'!$E$38,E9<'Reference Tab - Do not Delete'!$E$37),'Reference Tab - Do not Delete'!$D$38,'Reference Tab - Do not Delete'!$D$39))))) -> $50B - $B | AH9: =IF(H9="","DNA",IF(H9<=10,"Top 10",IF(AND(H9<=25,H9>10),"11 - 25",IF(AND(H9<=50,H9>25),"26 - 50","Above 50")))) -> Top 10 | AI9: =IF(AJ9>0,"Yes","") -> Yes | AJ9: 2500
A10: Roopak | B10: Allstate Ins Group | C10: 4 | D10: Carrier | E10: 34038467000 | F10: 0.054 | G10: 4 | H10: 4 | I10: US | J10: 85 | K10: Strategic | L10: Amit Gaba | M10: Tom Wilson | N10: Mario Rizzo | O10: Mark Prindiville | P10: Eric Brandt | Q10: Glenn Shapiro | R10: Suren Gupta | T10: Yes | U10: Genpact, Fractal | V10: Perpetual MSA | W10: ITP2 | AG10: =IF(E10="","",IF(E10>='Reference Tab - Do not Delete'!$E$35,'Reference Tab - Do not Delete'!$D$35,IF(AND(E10>='Reference Tab - Do not Delete'!$E$36,E10<'Reference Tab - Do not Delete'!$E$35),'Reference Tab - Do not Delete'!$D$36,IF(AND(E10>='Reference Tab - Do not Delete'!$E$37,E10<'Reference Tab - Do not Delete'!$E$36),'Reference Tab - Do not Delete'!$D$37,IF(AND(E10>='Reference Tab - Do not Delete'!$E$38,E10<'Reference Tab - Do not Delete'!$E$37),'Reference Tab - Do not Delete'!$D$38,'Reference Tab - Do not Delete'!$D$39))))) -> $50B - $B | AH10: =IF(H10="","DNA",IF(H10<=10,"Top 10",IF(AND(H10<=25,H10>10),"11 - 25",IF(AND(H10<=50,H10>25),"26 - 50","Above 50")))) -> Top 10 | AI10: =IF(AJ10>0,"Yes","") -> Yes | AJ10: 9190553.4 | AK10: Medium | AL10: Yes
A11: Nikhil | B11: Liberty Mutual Ins Cos | C11: 5 | D11: Carrier | E11: 32268379000 | F11: 0.014 | G11: 5 | H11: 5 | I11: US | J11: 101.7 | K11: Named | L11: Kuldeep | M11: David H. Long | N11: Christopher Pierce | R11: James McGlennon | T11: Yes | U11: CTS | W11: ITP1 | AG11: =IF(E11="","",IF(E11>='Reference Tab - Do not Delete'!$E$35,'Reference Tab - Do not Delete'!$D$35,IF(AND(E11>='Reference Tab - Do not Delete'!$E$36,E11<'Reference Tab - Do not Delete'!$E$35),'Reference Tab - Do not Delete'!$D$36,IF(AND(E11>='Reference Tab - Do not Delete'!$E$37,E11<'Reference Tab - Do not Delete'!$E$36),'Reference Tab - Do not Delete'!$D$37,IF(AND(E11>='Reference Tab - Do not Delete'!$E$38,E11<'Reference Tab - Do not Delete'!$E$37),'Reference Tab - Do not Delete'!$D$38,'Reference Tab - Do not Delete'!$D$39))))) -> $50B - $B | AH11: =IF(H11="","DNA",IF(H11<=10,"Top 10",IF(AND(H11<=25,H11>10),"11 - 25",IF(AND(H11<=50,H11>25),"26 - 50","Above 50")))) -> Top 10 | AI11: =IF(AJ11>0,"Yes","") -> Yes | AJ11: 8246886.5 | AK11: Medium | AL11: Yes
A12: Sean | B12: Travelers Group | C12: 6 | D12: Carrier | E12: 27214083000 | F12: 0.055 | G12: 6 | H12: 6 | I12: US | J12: 96.5 | K12: Named | L12: Sean | M12: Alan Schnitzer | N12: Dan Frey | O12: Bruce Jones | P12: Nicolas Seminara | Q12: Mojgan Lefebvre | R12: Mojgan Lefebvre | S12: Rick Schug | T12: Yes | U12: CTS, WNS, Genpact | V12: 2021 | W12: ITP2 | AG12: =IF(E12="","",IF(E12>='Reference Tab - Do not Delete'!$E$35,'Reference Tab - Do not Delete'!$D$35,IF(AND(E12>='Reference Tab - Do not Delete'!$E$36,E12<'Reference Tab - Do not Delete'!$E$35),'Reference Tab - Do not Delete'!$D$36,IF(AND(E12>='Reference Tab - Do not Delete'!$E$37,E12<'Reference Tab - Do not Delete'!$E$36),'Reference Tab - Do not Delete'!$D$37,IF(AND(E12>='Reference Tab - Do not Delete'!$E$38,E12<'Reference Tab - Do not Delete'!$E$37),'Reference Tab - Do not Delete'!$D$38,'Reference Tab - Do not Delete'!$D$39))))) -> $50B - $B | AH12: =IF(H12="","DNA",IF(H12<=10,"Top 10",IF(AND(H12<=25,H12>10),"11 - 25",IF(AND(H12<=50,H12>25),"26 - 50","Above 50")))) -> Top 10 | AI12: =IF(AJ12>0,"Yes","") | AJ12: 0
A13: Sean | B13: USAA Group | C13: 7 | D13: Carrier | E13: 22981339000 | F13: 0.069 | G13: 7 | H13: 7 | I13: US | J13: 82.8 | K13: Named | L13: Sean | M13: Wayne Peacock | N13: Laura Bishop | O13: Torben Ostergaard | P13: Sean Burgess | R13: Michael Brady | T13: Yes | U13: TCS | W13: ITP3 | AG13: =IF(E13="","",IF(E13>='Reference Tab - Do not Delete'!$E$35,'Reference Tab - Do not Delete'!$D$35,IF(AND(E13>='Reference Tab - Do not Delete'!$E$36,E13<'Reference Tab - Do not Delete'!$E$35),'Reference Tab - Do not Delete'!$D$36,IF(AND(E13>='Reference Tab - Do not Delete'!$E$37,E13<'Reference Tab - Do not Delete'!$E$36),'Reference Tab - Do not Delete'!$D$37,IF(AND(E13>='Reference Tab - Do not Delete'!$E$38,E13<'Reference Tab - Do not Delete'!$E$37),'Reference Tab - Do not Delete'!$D$38,'Reference Tab - Do not Delete'!$D$39))))) -> $50B - $B | AH13: =IF(H13="","DNA",IF(H13<=10,"Top 10",IF(AND(H13<=25,H13>10),"11 - 25",IF(AND(H13<=50,H13>25),"26 - 50","Above 50")))) -> Top 10 | AI13: =IF(AJ13>0,"Yes","") -> Yes | AJ13: 3515776.7
B14: Chubb INA Group | C14: 8 | D14: Carrier | E14: 18249079000 | F14: -0.067 | G14: 8 | H14: 8 | I14: US | W14: ITP2 | AG14: =IF(E14="","",IF(E14>='Reference Tab - Do not Delete'!$E$35,'Reference Tab - Do not Delete'!$D$35,IF(AND(E14>='Reference Tab - Do not Delete'!$E$36,E14<'Reference Tab - Do not Delete'!$E$35),'Reference Tab - Do not Delete'!$D$36,IF(AND(E14>='Reference Tab - Do not Delete'!$E$37,E14<'Reference Tab - Do not Delete'!$E$36),'Reference Tab - Do not Delete'!$D$37,IF(AND(E14>='Reference Tab - Do not Delete'!$E$38,E14<'Reference Tab - Do not Delete'!$E$37),'Reference Tab - Do not Delete'!$D$38,'Reference Tab - Do not Delete'!$D$39))))) -> $50B - $B | AH14: =IF(H14="","DNA",IF(H14<=10,"Top 10",IF(AND(H14<=25,H14>10),"11 - 25",IF(AND(H14<=50,H14>25),"26 - 50","Above 50")))) -> Top 10 | AI14: =IF(AJ14>0,"Yes","") -> Yes | AJ14: 540548.98
A15: Mohit | B15: Nationwide Group | C15: 9 | D15: Carrier | E15: 17992806000 | F15: -0.008 | G15: 9 | H15: 9 | I15: US | J15: 94 | K15: Named | L15: Mohit | M15: Kirt Walker | N15: Mark Thresher | O15: Klaus Diem | P15: Sandra Rich | Q15: Mark Berven | R15: James Fowler | T15: Yes | U15: CTS, Genpact | V15: Mid 2021, 2022 | W15: ITP1 | AG15: =IF(E15="","",IF(E15>='Reference Tab - Do not Delete'!$E$35,'Reference Tab - Do not Delete'!$D$35,IF(AND(E15>='Reference Tab - Do not Delete'!$E$36,E15<'Reference Tab - Do not Delete'!$E$35),'Reference Tab - Do not Delete'!$D$36,IF(AND(E15>='Reference Tab - Do not Delete'!$E$37,E15<'Reference Tab - Do not Delete'!$E$36),'Reference Tab - Do not Delete'!$D$37,IF(AND(E15>='Reference Tab - Do not Delete'!$E$38,E15<'Reference Tab - Do not Delete'!$E$37),'Reference Tab - Do not Delete'!$D$38,'Reference Tab - Do not Delete'!$D$39))))) -> $50B - $B | AH15: =IF(H15="","DNA",IF(H15<=10,"Top 10",IF(AND(H15<=25,H15>10),"11 - 25",IF(AND(H15<=50,H15>25),"26 - 50","Above 50")))) -> Top 10 | AI15: =IF(AJ15>0,"Yes","") | AJ15: 0
B16: Amer Intl Group | C16: 10 | D16: Carrier | E16: 14825888000 | F16: 0.015 | G16: 10 | H16: 10 | I16: US | T16: Yes | U16: CTS | W16: ITP2 | AG16: =IF(E16="","",IF(E16>='Reference Tab - Do not Delete'!$E$35,'Reference Tab - Do not Delete'!$D$35,IF(AND(E16>='Reference Tab - Do not Delete'!$E$36,E16<'Reference Tab - Do not Delete'!$E$35),'Reference Tab - Do not Delete'!$D$36,IF(AND(E16>='Reference Tab - Do not Delete'!$E$37,E16<'Reference Tab - Do not Delete'!$E$36),'Reference Tab - Do not Delete'!$D$37,IF(AND(E16>='Reference Tab - Do not Delete'!$E$38,E16<'Reference Tab - Do not Delete'!$E$37),'Reference Tab - Do not Delete'!$D$38,'Reference Tab - Do not Delete'!$D$39))))) -> $50B - $B | AH16: =IF(H16="","DNA",IF(H16<=10,"Top 10",IF(AND(H16<=25,H16>10),"11 - 25",IF(AND(H16<=50,H16>25),"26 - 50","Above 50")))) -> Top 10 | AI16: =IF(AJ16>0,"Yes","") | AJ16: 0
A17: Sean | B17: Farmers Ins Group | C17: 11 | D17: Carrier | E17: 14483557000 | F17: 0.033 | G17: 11 | H17: 11 | I17: US | K17: Named | L17: Sean | M17: Jeff Dailey | N17: Scott Lindquist | P17: Rob Howard | R17: Paul Wilson | T17: Yes | W17: ITP3 | AG17: =IF(E17="","",IF(E17>='Reference Tab - Do not Delete'!$E$35,'Reference Tab - Do not Delete'!$D$35,IF(AND(E17>='Reference Tab - Do not Delete'!$E$36,E17<'Reference Tab - Do not Delete'!$E$35),'Reference Tab - Do not Delete'!$D$36,IF(AND(E17>='Reference Tab - Do not Delete'!$E$37,E17<'Reference Tab - Do not Delete'!$E$36),'Reference Tab - Do not Delete'!$D$37,IF(AND(E17>='Reference Tab - Do not Delete'!$E$38,E17<'Reference Tab - Do not Delete'!$E$37),'Reference Tab - Do not Delete'!$D$38,'Reference Tab - Do not Delete'!$D$39))))) -> $50B - $B | AH17: =IF(H17="","DNA",IF(H17<=10,"Top 10",IF(AND(H17<=25,H17>10),"11 - 25",IF(AND(H17<=50,H17>25),"26 - 50","Above 50")))) -> 11 - 25 | AI17: =IF(AJ17>0,"Yes","") -> Yes | AJ17: 3745787.8
A18: Saju | B18: Hartford Ins Group | C18: 12 | D18: Carrier | E18: 11871251000 | F18: 0.032 | G18: 12 | H18: 12 | I18: US | J18: 94 | K18: Strategic | L18: Kuldeep | M18: Chris Swift | N18: Beth Costello | O18: Robert Paiano | P18: John Kinney | Q18: Bill Bloom | R18: Bill Bloom | S18: Ross Fisher | T18: Yes | U18: CTS | V18: 45627 | W18: ITP2 | AG18: =IF(E18="","",IF(E18>='Reference Tab - Do not Delete'!$E$35,'Reference Tab - Do not Delete'!$D$35,IF(AND(E18>='Reference Tab - Do not Delete'!$E$36,E18<'Reference Tab - Do not Delete'!$E$35),'Reference Tab - Do not Delete'!$D$36,IF(AND(E18>='Reference Tab - Do not Delete'!$E$37,E18<'Reference Tab - Do not Delete'!$E$36),'Reference Tab - Do not Delete'!$D$37,IF(AND(E18>='Reference Tab - Do not Delete'!$E$38,E18<'Reference Tab - Do not Delete'!$E$37),'Reference Tab - Do not Delete'!$D$38,'Reference Tab - Do not Delete'!$D$39))))) -> $50B - $B | AH18: =IF(H18="","DNA",IF(H18<=10,"Top 10",IF(AND(H18<=25,H18>10),"11 - 25",IF(AND(H18<=50,H18>25),"26 - 50","Above 50")))) -> 11 - 25 | AI18: =IF(AJ18>0,"Yes","") -> Yes | AJ18: 18364859 | AK18: Medium | AL18: Yes
A19: Sean | B19: Amer Family Ins Group | C19: 13 | D19: Carrier | E19: 11841650000 | F19: 0.043 | G19: 13 | H19: 13 | I19: US | J19: 105.7 | K19: Named | L19: Sean | M19: Jack Charles Salzwedel | N19: Dan Kelly | O19: Joseph Gates | P19: Scott Little | R19: Kristen Kirkconnel | T19: Yes | W19: ITP3 | AG19: =IF(E19="","",IF(E19>='Reference Tab - Do not Delete'!$E$35,'Reference Tab - Do not Delete'!$D$35,IF(AND(E19>='Reference Tab - Do not Delete'!$E$36,E19<'Reference Tab - Do not Delete'!$E$35),'Reference Tab - Do not Delete'!$D$36,IF(AND(E19>='Reference Tab - Do not Delete'!$E$37,E19<'Reference Tab - Do not Delete'!$E$36),'Reference Tab - Do not Delete'!$D$37,IF(AND(E19>='Reference Tab - Do not Delete'!$E$38,E19<'Reference Tab - Do not Delete'!$E$37),'Reference Tab - Do not Delete'!$D$38,'Reference Tab - Do not Delete'!$D$39))))) -> $50B - $B | AH19: =IF(H19="","DNA",IF(H19<=10,"Top 10",IF(AND(H19<=25,H19>10),"11 - 25",IF(AND(H19<=50,H19>25),"26 - 50","Above 50")))) -> 11 - 25 | AI19: =IF(AJ19>0,"Yes","") -> Yes | AJ19: 7000
B20: Auto-Owners Ins Group | C20: 14 | D20: Carrier | E20: 8585830000 | F20: 0.074 | G20: 14 | H20: 14 | I20: US | AG20: =IF(E20="","",IF(E20>='Reference Tab - Do not Delete'!$E$35,'Reference Tab - Do not Delete'!$D$35,IF(AND(E20>='Reference Tab - Do not Delete'!$E$36,E20<'Reference Tab - Do not Delete'!$E$35),'Reference Tab - Do not Delete'!$D$36,IF(AND(E20>='Reference Tab - Do not Delete'!$E$37,E20<'Reference Tab - Do not Delete'!$E$36),'Reference Tab - Do not Delete'!$D$37,IF(AND(E20>='Reference Tab - Do not Delete'!$E$38,E20<'Reference Tab - Do not Delete'!$E$37),'Reference Tab - Do not Delete'!$D$38,'Reference Tab - Do not Delete'!$D$39))))) -> $50B - $B | AH20: =IF(H20="","DNA",IF(H20<=10,"Top 10",IF(AND(H20<=25,H20>10),"11 - 25",IF(AND(H20<=50,H20>25),"26 - 50","Above 50")))) -> 11 - 25 | AI20: =IF(AJ20>0,"Yes","") -> Yes | AJ20: 1000
B21: Fairfax Financial (USA) Group | C21: 15 | D21: Carrier | E21: 7632626000 | F21: 0.098 | G21: 15 | H21: 17 | I21: US | W21: ITP1 | AG21: =IF(E21="","",IF(E21>='Reference Tab - Do not Delete'!$E$35,'Reference Tab - Do not Delete'!$D$35,IF(AND(E21>='Reference Tab - Do not Delete'!$E$36,E21<'Reference Tab - Do not Delete'!$E$35),'Reference Tab - Do not Delete'!$D$36,IF(AND(E21>='Reference Tab - Do not Delete'!$E$37,E21<'Reference Tab - Do not Delete'!$E$36),'Reference Tab - Do not Delete'!$D$37,IF(AND(E21>='Reference Tab - Do not Delete'!$E$38,E21<'Reference Tab - Do not Delete'!$E$37),'Reference Tab - Do not Delete'!$D$38,'Reference Tab - Do not Delete'!$D$39))))) -> $50B - $B | AH21: =IF(H21="","DNA",IF(H21<=10,"Top 10",IF(AND(H21<=25,H21>10),"11 - 25",IF(AND(H21<=50,H21>25),"26 - 50","Above 50")))) -> 11 - 25 | AI21: =IF(AJ21>0,"Yes","") | AJ21: 0
B22: Erle Ins Group | C22: 16 | D22: Carrier | E22: 7478390000 | F22: 0.055 | G22: 16 | H22: 16 | I22: US | W22: ITP2 | AG22: =IF(E22="","",IF(E22>='Reference Tab - Do not Delete'!$E$35,'Reference Tab - Do not Delete'!$D$35,IF(AND(E22>='Reference Tab - Do not Delete'!$E$36,E22<'Reference Tab - Do not Delete'!$E$35),'Reference Tab - Do not Delete'!$D$36,IF(AND(E22>='Reference Tab - Do not Delete'!$E$37,E22<'Reference Tab - Do not Delete'!$E$36),'Reference Tab - Do not Delete'!$D$37,IF(AND(E22>='Reference Tab - Do not Delete'!$E$38,E22<'Reference Tab - Do not Delete'!$E$37),'Reference Tab - Do not Delete'!$D$38,'Reference Tab - Do not Delete'!$D$39))))) -> $50B - $B | AH22: =IF(H22="","DNA",IF(H22<=10,"Top 10",IF(AND(H22<=25,H22>10),"11 - 25",IF(AND(H22<=50,H22>25),"26 - 50","Above 50")))) -> 11 - 25 | AI22: =IF(AJ22>0,"Yes","") | AJ22: 0
B23: Tokio Marina US PC Group | C23: 17 | D23: Carrier | E23: 7083699000 | F23: 0.052 | G23: 17 | H23: 19 | I23: US | W23: ITP3 | AG23: =IF(E23="","",IF(E23>='Reference Tab - Do not Delete'!$E$35,'Reference Tab - Do not Delete'!$D$35,IF(AND(E23>='Reference Tab - Do not Delete'!$E$36,E23<'Reference Tab - Do not Delete'!$E$35),'Reference Tab - Do not Delete'!$D$36,IF(AND(E23>='Reference Tab - Do not Delete'!$E$37,E23<'Reference Tab - Do not Delete'!$E$36),'Reference Tab - Do not Delete'!$D$37,IF(AND(E23>='Reference Tab - Do not Delete'!$E$38,E23<'Reference Tab - Do not Delete'!$E$37),'Reference Tab - Do not Delete'!$D$38,'Reference Tab - Do not Delete'!$D$39))))) -> $50B - $B | AH23: =IF(H23="","DNA",IF(H23<=10,"Top 10",IF(AND(H23<=25,H23>10),"11 - 25",IF(AND(H23<=50,H23>25),"26 - 50","Above 50")))) -> 11 - 25 | AI23: =IF(AJ23>0,"Yes","") -> Yes | AJ23: 300
A24: Saju | B24: CNA Ins Cos | C24: 18 | D24: Carrier | E24: 6953530000 | F24: 0.059 | G24: 18 | H24: 20 | I24: US | J24: 94.8 | K24: Strategic | L24: Roopak | M24: Dino Robusto | N24: Al Miralles | P24: Daniel Franzetti | Q24: Kevin Leidwinger | R24: Michael Costonis | S24: Douglas M. Worman | T24: Yes | V24: 44562 | AG24: =IF(E24="","",IF(E24>='Reference Tab - Do not Delete'!$E$35,'Reference Tab - Do not Delete'!$D$35,IF(AND(E24>='Reference Tab - Do not Delete'!$E$36,E24<'Reference Tab - Do not Delete'!$E$35),'Reference Tab - Do not Delete'!$D$36,IF(AND(E24>='Reference Tab - Do not Delete'!$E$37,E24<'Reference Tab - Do not Delete'!$E$36),'Reference Tab - Do not Delete'!$D$37,IF(AND(E24>='Reference Tab - Do not Delete'!$E$38,E24<'Reference Tab - Do not Delete'!$E$37),'Reference Tab - Do not Delete'!$D$38,'Reference Tab - Do not Delete'!$D$39))))) -> $50B - $B | AH24: =IF(H24="","DNA",IF(H24<=10,"Top 10",IF(AND(H24<=25,H24>10),"11 - 25",IF(AND(H24<=50,H24>25),"26 - 50","Above 50")))) -> 11 - 25 | AI24: =IF(AJ24>0,"Yes","") -> Yes | AJ24: 11816240 | AK24: Medium | AL24: Yes
A25: Mohit | B25: Munich-Amer Hldg Corp Cos | C25: 19 | D25: Carrier | E25: 6639450000 | F25: -0.025 | G25: 19 | H25: 18 | I25: US | J25: 101 | K25: Named | L25: Mohit | M25: Dave Brune | N25: Oliver J. Horbelt/Angela Homm | O25: Catherine Smith | P25: JannaLyn Allen | Q25: Anita Kuchma | R25: Phil Roeper | T25: Yes | U25: Wipro,Capgemini | V25: Sep, 2022 (with Wipro) and 23rd July 2020 with Capgemini | W25: ITP1 | AG25: =IF(E25="","",IF(E25>='Reference Tab - Do not Delete'!$E$35,'Reference Tab - Do not Delete'!$D$35,IF(AND(E25>='Reference Tab - Do not Delete'!$E$36,E25<'Reference Tab - Do not Delete'!$E$35),'Reference Tab - Do not Delete'!$D$36,IF(AND(E25>='Reference Tab - Do not Delete'!$E$37,E25<'Reference Tab - Do not Delete'!$E$36),'Reference Tab - Do not Delete'!$D$37,IF(AND(E25>='Reference Tab - Do not Delete'!$E$38,E25<'Reference Tab - Do not Delete'!$E$37),'Reference Tab - Do not Delete'!$D$38,'Reference Tab - Do not Delete'!$D$39))))) -> $50B - $B | AH25: =IF(H25="","DNA",IF(H25<=10,"Top 10",IF(AND(H25<=25,H25>10),"11 - 25",IF(AND(H25<=50,H25>25),"26 - 50","Above 50")))) -> 11 - 25 | AI25: =IF(AJ25>0,"Yes","") | AJ25: 0
B26: W. R. Berkley Ins Group | C26: 20 | D26: Carrier | E26: 6131338000 | F26: 0.071 | G26: 20 | H26: 21 | I26: US | W26: ITP2 | AG26: =IF(E26="","",IF(E26>='Reference Tab - Do not Delete'!$E$35,'Reference Tab - Do not Delete'!$D$35,IF(AND(E26>='Reference Tab - Do not Delete'!$E$36,E26<'Reference Tab - Do not Delete'!$E$35),'Reference Tab - Do not Delete'!$D$36,IF(AND(E26>='Reference Tab - Do not Delete'!$E$37,E26<'Reference Tab - Do not Delete'!$E$36),'Reference Tab - Do not Delete'!$D$37,IF(AND(E26>='Reference Tab - Do not Delete'!$E$38,E26<'Reference Tab - Do not Delete'!$E$37),'Reference Tab - Do not Delete'!$D$38,'Reference Tab - Do not Delete'!$D$39))))) -> $50B - $B | AH26: =IF(H26="","DNA",IF(H26<=10,"Top 10",IF(AND(H26<=25,H26>10),"11 - 25",IF(AND(H26<=50,H26>25),"26 - 50","Above 50")))) -> 11 - 25 | AI26: =IF(AJ26>0,"Yes","") | AJ26: 0
A27: Sean | B27: Everest Re US Group | C27: 21 | D27: Carrier | E27: 5797634000 | F27: 0.148 | G27: 21 | H27: 22 | I27: US | J27: 88.7 | K27: Named | L27: Sean | M27: Mike Karmilowicz | N27: Dana Lodge | O27: Bill Thygeson, CAO | P27: Patricia Mcmahon | Q27: Mike Mulray | R27: Owen Williams | S27: Open | T27: Yes | U27: None | V27: 2023 | AG27: =IF(E27="","",IF(E27>='Reference Tab - Do not Delete'!$E$35,'Reference Tab - Do not Delete'!$D$35,IF(AND(E27>='Reference Tab - Do not Delete'!$E$36,E27<'Reference Tab - Do not Delete'!$E$35),'Reference Tab - Do not Delete'!$D$36,IF(AND(E27>='Reference Tab - Do not Delete'!$E$37,E27<'Reference Tab - Do not Delete'!$E$36),'Reference Tab - Do not Delete'!$D$37,IF(AND(E27>='Reference Tab - Do not Delete'!$E$38,E27<'Reference Tab - Do not Delete'!$E$37),'Reference Tab - Do not Delete'!$D$38,'Reference Tab - Do not Delete'!$D$39))))) -> $50B - $B | AH27: =IF(H27="","DNA",IF(H27<=10,"Top 10",IF(AND(H27<=25,H27>10),"11 - 25",IF(AND(H27<=50,H27>25),"26 - 50","Above 50")))) -> 11 - 25 | AI27: =IF(AJ27>0,"Yes","") -> Yes | AJ27: 1214372.9
B28: Cincinnati Ins Cos | C28: 22 | D28: Carrier | E28: 5379896000 | F28: 0.069 | G28: 22 | H28: 23 | I28: US | AG28: =IF(E28="","",IF(E28>='Reference Tab - Do not Delete'!$E$35,'Reference Tab - Do not Delete'!$D$35,IF(AND(E28>='Reference Tab - Do not Delete'!$E$36,E28<'Reference Tab - Do not Delete'!$E$35),'Reference Tab - Do not Delete'!$D$36,IF(AND(E28>='Reference Tab - Do not Delete'!$E$37,E28<'Reference Tab - Do not Delete'!$E$36),'Reference Tab - Do not Delete'!$D$37,IF(AND(E28>='Reference Tab - Do not Delete'!$E$38,E28<'Reference Tab - Do not Delete'!$E$37),'Reference Tab - Do not Delete'!$D$38,'Reference Tab - Do not Delete'!$D$39))))) -> $50B - $B | AH28: =IF(H28="","DNA",IF(H28<=10,"Top 10",IF(AND(H28<=25,H28>10),"11 - 25",IF(AND(H28<=50,H28>25),"26 - 50","Above 50")))) -> 11 - 25 | AI28: =IF(AJ28>0,"Yes","") | AJ28: 0
B29: Alleghany Corp Group | C29: 23 | D29: Carrier | E29: 5344634000 | F29: 0.145 | G29: 23 | H29: 24 | I29: US | W29: ITP1 | AG29: =IF(E29="","",IF(E29>='Reference Tab - Do not Delete'!$E$35,'Reference Tab - Do not Delete'!$D$35,IF(AND(E29>='Reference Tab - Do not Delete'!$E$36,E29<'Reference Tab - Do not Delete'!$E$35),'Reference Tab - Do not Delete'!$D$36,IF(AND(E29>='Reference Tab - Do not Delete'!$E$37,E29<'Reference Tab - Do not Delete'!$E$36),'Reference Tab - Do not Delete'!$D$37,IF(AND(E29>='Reference Tab - Do not Delete'!$E$38,E29<'Reference Tab - Do not Delete'!$E$37),'Reference Tab - Do not Delete'!$D$38,'Reference Tab - Do not Delete'!$D$39))))) -> $50B - $B | AH29: =IF(H29="","DNA",IF(H29<=10,"Top 10",IF(AND(H29<=25,H29>10),"11 - 25",IF(AND(H29<=50,H29>25),"26 - 50","Above 50")))) -> 11 - 25 | AI29: =IF(AJ29>0,"Yes","") | AJ29: 0
A30: Sean | B30: Great Amer P&C Ins Group | C30: 24 | D30: Carrier | E30: 4689656000 | F30: 0.079 | G30: 24 | H30: 26 | I30: US | J30: 93.7 | K30: Named | L30: Sean | M30: Carl Lindnor, Craig Lindnor | N30: Jeff Consolino | Q30: Gary Gruber | R30: Chad Stewart | T30: Yes | W30: ITP3 | AG30: =IF(E30="","",IF(E30>='Reference Tab - Do not Delete'!$E$35,'Reference Tab - Do not Delete'!$D$35,IF(AND(E30>='Reference Tab - Do not Delete'!$E$36,E30<'Reference Tab - Do not Delete'!$E$35),'Reference Tab - Do not Delete'!$D$36,IF(AND(E30>='Reference Tab - Do not Delete'!$E$37,E30<'Reference Tab - Do not Delete'!$E$36),'Reference Tab - Do not Delete'!$D$37,IF(AND(E30>='Reference Tab - Do not Delete'!$E$38,E30<'Reference Tab - Do not Delete'!$E$37),'Reference Tab - Do not Delete'!$D$38,'Reference Tab - Do not Delete'!$D$39))))) -> $50B - $B | AH30: =IF(H30="","DNA",IF(H30<=10,"Top 10",IF(AND(H30<=25,H30>10),"11 - 25",IF(AND(H30<=50,H30>25),"26 - 50","Above 50")))) -> 26 - 50 | AI30: =IF(AJ30>0,"Yes","") | AJ30: 0
A31: Saju | B31: Hanover Ins Group Prop & Cas Cos | C31: 25 | D31: Carrier | E31: 4580867000 | F31: 0.042 | G31: 25 | H31: 25 | I31: US | J31: 95.6 | K31: Strategic | L31: Aditya Chaturvedi | M31: John "Jack" Roche | N31: Jeff Farber | O31: Catherine Eska | P31: Mark Welzenbach | Q31: Gayle Falvey - CL Michele Streton - PL | R31: Mark Berthiaume | S31: Chip Hamann (Small Commercial) | T31: Yes | U31: CTS, NTT, PWC | V31: 44531 | AG31: =IF(E31="","",IF(E31>='Reference Tab - Do not Delete'!$E$35,'Reference Tab - Do not Delete'!$D$35,IF(AND(E31>='Reference Tab - Do not Delete'!$E$36,E31<'Reference Tab - Do not Delete'!$E$35),'Reference Tab - Do not Delete'!$D$36,IF(AND(E31>='Reference Tab - Do not Delete'!$E$37,E31<'Reference Tab - Do not Delete'!$E$36),'Reference Tab - Do not Delete'!$D$37,IF(AND(E31>='Reference Tab - Do not Delete'!$E$38,E31<'Reference Tab - Do not Delete'!$E$37),'Reference Tab - Do not Delete'!$D$38,'Reference Tab - Do not Delete'!$D$39))))) -> $50B - $B | AH31: =IF(H31="","DNA",IF(H31<=10,"Top 10",IF(AND(H31<=25,H31>10),"11 - 25",IF(AND(H31<=50,H31>25),"26 - 50","Above 50")))) -> 11 - 25 | AI31: =IF(AJ31>0,"Yes","") -> Yes | AJ31: 12214610 | AK31: Medium | AL31: Yes
B32: Auto Club Enterprises Ins Group | C32: 26 | D32: Carrier | E32: 4546591000 | F32: 0.053 | G32: 26 | H32: 27 | I32: US | AG32: =IF(E32="","",IF(E32>='Reference Tab - Do not Delete'!$E$35,'Reference Tab - Do not Delete'!$D$35,IF(AND(E32>='Reference Tab - Do not Delete'!$E$36,E32<'Reference Tab - Do not Delete'!$E$35),'Reference Tab - Do not Delete'!$D$36,IF(AND(E32>='Reference Tab - Do not Delete'!$E$37,E32<'Reference Tab - Do not Delete'!$E$36),'Reference Tab - Do not Delete'!$D$37,IF(AND(E32>='Reference Tab - Do not Delete'!$E$38,E32<'Reference Tab - Do not Delete'!$E$37),'Reference Tab - Do not Delete'!$D$38,'Reference Tab - Do not Delete'!$D$39))))) -> $50B - $B | AH32: =IF(H32="","DNA",IF(H32<=10,"Top 10",IF(AND(H32<=25,H32>10),"11 - 25",IF(AND(H32<=50,H32>25),"26 - 50","Above 50")))) -> 26 - 50 | AI32: =IF(AJ32>0,"Yes","") | AJ32: 0
B33: Allianz US PC Ins Companies | C33: 27 | D33: Carrier | E33: 4091021000 | F33: 0.536 | G33: 27 | H33: 40 | I33: US | W33: ITP1 | AG33: =IF(E33="","",IF(E33>='Reference Tab - Do not Delete'!$E$35,'Reference Tab - Do not Delete'!$D$35,IF(AND(E33>='Reference Tab - Do not Delete'!$E$36,E33<'Reference Tab - Do not Delete'!$E$35),'Reference Tab - Do not Delete'!$D$36,IF(AND(E33>='Reference Tab - Do not Delete'!$E$37,E33<'Reference Tab - Do not Delete'!$E$36),'Reference Tab - Do not Delete'!$D$37,IF(AND(E33>='Reference Tab - Do not Delete'!$E$38,E33<'Reference Tab - Do not Delete'!$E$37),'Reference Tab - Do not Delete'!$D$38,'Reference Tab - Do not Delete'!$D$39))))) -> $50B - $B | AH33: =IF(H33="","DNA",IF(H33<=10,"Top 10",IF(AND(H33<=25,H33>10),"11 - 25",IF(AND(H33<=50,H33>25),"26 - 50","Above 50")))) -> 26 - 50 | AI33: =IF(AJ33>0,"Yes","") | AJ33: 0
A34: Roopak | B34: Kemper PC Companies | C34: 28 | D34: Carrier | E34: 4042228000 | F34: 0.085 | G34: 28 | H34: 30 | I34: US | J34: 93 | K34: Named | L34: Amit Gaba | M34: Joe Lacher | N34: Jim McKinney | O34: Max Mindak | P34: Kim Leggette | Q34: Duane Sanders | R34: Charles Brooks | T34: Yes | U34: Accenture | V34: 44197 | W34: ITP2 | AG34: =IF(E34="","",IF(E34>='Reference Tab - Do not Delete'!$E$35,'Reference Tab - Do not Delete'!$D$35,IF(AND(E34>='Reference Tab - Do not Delete'!$E$36,E34<'Reference Tab - Do not Delete'!$E$35),'Reference Tab - Do not Delete'!$D$36,IF(AND(E34>='Reference Tab - Do not Delete'!$E$37,E34<'Reference Tab - Do not Delete'!$E$36),'Reference Tab - Do not Delete'!$D$37,IF(AND(E34>='Reference Tab - Do not Delete'!$E$38,E34<'Reference Tab - Do not Delete'!$E$37),'Reference Tab - Do not Delete'!$D$38,'Reference Tab - Do not Delete'!$D$39))))) -> $50B - $B | AH34: =IF(H34="","DNA",IF(H34<=10,"Top 10",IF(AND(H34<=25,H34>10),"11 - 25",IF(AND(H34<=50,H34>25),"26 - 50","Above 50")))) -> 26 - 50 | AI34: =IF(AJ34>0,"Yes","") -> Yes | AJ34: 2825296.4 | AK34: Medium | AL34: Yes
B35: CSAA Ins Group | C35: 29 | D35: Carrier | E35: 4031220000 | F35: 0.015 | G35: 29 | H35: 28 | I35: US | AG35: =IF(E35="","",IF(E35>='Reference Tab - Do not Delete'!$E$35,'Reference Tab - Do not Delete'!$D$35,IF(AND(E35>='Reference Tab - Do not Delete'!$E$36,E35<'Reference Tab - Do not Delete'!$E$35),'Reference Tab - Do not Delete'!$D$36,IF(AND(E35>='Reference Tab - Do not Delete'!$E$37,E35<'Reference Tab - Do not Delete'!$E$36),'Reference Tab - Do not Delete'!$D$37,IF(AND(E35>='Reference Tab - Do not Delete'!$E$38,E35<'Reference Tab - Do not Delete'!$E$37),'Reference Tab - Do not Delete'!$D$38,'Reference Tab - Do not Delete'!$D$39))))) -> $50B - $B | AH35: =IF(H35="","DNA",IF(H35<=10,"Top 10",IF(AND(H35<=25,H35>10),"11 - 25",IF(AND(H35<=50,H35>25),"26 - 50","Above 50")))) -> 26 - 50 | AI35: =IF(AJ35>0,"Yes","") | AJ35: 0
B36: FM Global Group | C36: 30 | D36: Carrier | E36: 4007616000 | F36: 0.104 | G36: 30 | H36: 32 | I36: US | AG36: =IF(E36="","",IF(E36>='Reference Tab - Do not Delete'!$E$35,'Reference Tab - Do not Delete'!$D$35,IF(AND(E36>='Reference Tab - Do not Delete'!$E$36,E36<'Reference Tab - Do not Delete'!$E$35),'Reference Tab - Do not Delete'!$D$36,IF(AND(E36>='Reference Tab - Do not Delete'!$E$37,E36<'Reference Tab - Do not Delete'!$E$36),'Reference Tab - Do not Delete'!$D$37,IF(AND(E36>='Reference Tab - Do not Delete'!$E$38,E36<'Reference Tab - Do not Delete'!$E$37),'Reference Tab - Do not Delete'!$D$38,'Reference Tab - Do not Delete'!$D$39))))) -> $50B - $B | AH36: =IF(H36="","DNA",IF(H36<=10,"Top 10",IF(AND(H36<=25,H36>10),"11 - 25",IF(AND(H36<=50,H36>25),"26 - 50","Above 50")))) -> 26 - 50 | AI36: =IF(AJ36>0,"Yes","") | AJ36: 0
B37: Markel Corp Group | C37: 31 | D37: Carrier | E37: 3809277000 | F37: 0.216 | G37: 31 | H37: 36 | I37: US | AG37: =IF(E37="","",IF(E37>='Reference Tab - Do not Delete'!$E$35,'Reference Tab - Do not Delete'!$D$35,IF(AND(E37>='Reference Tab - Do not Delete'!$E$36,E37<'Reference Tab - Do not Delete'!$E$35),'Reference Tab - Do not Delete'!$D$36,IF(AND(E37>='Reference Tab - Do not Delete'!$E$37,E37<'Reference Tab - Do not Delete'!$E$36),'Reference Tab - Do not Delete'!$D$37,IF(AND(E37>='Reference Tab - Do not Delete'!$E$38,E37<'Reference Tab - Do not Delete'!$E$37),'Reference Tab - Do not Delete'!$D$38,'Reference Tab - Do not Delete'!$D$39))))) -> $50B - $B | AH37: =IF(H37="","DNA",IF(H37<=10,"Top 10",IF(AND(H37<=25,H37>10),"11 - 25",IF(AND(H37<=50,H37>25),"26 - 50","Above 50")))) -> 26 - 50 | AI37: =IF(AJ37>0,"Yes","") | AJ37: 0
B38: MetLife Auto & Home Group | C38: 32 | D38: Carrier | E38: 3797476000 | F38: 0.02 | G38: 32 | H38: 31 | I38: US | W38: ITP1 | AG38: =IF(E38="","",IF(E38>='Reference Tab - Do not Delete'!$E$35,'Reference Tab - Do not Delete'!$D$35,IF(AND(E38>='Reference Tab - Do not Delete'!$E$36,E38<'Reference Tab - Do not Delete'!$E$35),'Reference Tab - Do not Delete'!$D$36,IF(AND(E38>='Reference Tab - Do not Delete'!$E$37,E38<'Reference Tab - Do not Delete'!$E$36),'Reference Tab - Do not Delete'!$D$37,IF(AND(E38>='Reference Tab - Do not Delete'!$E$38,E38<'Reference Tab - Do not Delete'!$E$37),'Reference Tab - Do not Delete'!$D$38,'Reference Tab - Do not Delete'!$D$39))))) -> $50B - $B | AH38: =IF(H38="","DNA",IF(H38<=10,"Top 10",IF(AND(H38<=25,H38>10),"11 - 25",IF(AND(H38<=50,H38>25),"26 - 50","Above 50")))) -> 26 - 50 | AI38: =IF(AJ38>0,"Yes","") -> Yes | AJ38: 2433250
B39: Mercury Gen Group | C39: 33 | D39: Carrier | E39: 3690508000 | F39: 0.067 | G39: 33 | H39: 34 | I39: US | W39: ITP3 | AG39: =IF(E39="","",IF(E39>='Reference Tab - Do not Delete'!$E$35,'Reference Tab - Do not Delete'!$D$35,IF(AND(E39>='Reference Tab - Do not Delete'!$E$36,E39<'Reference Tab - Do not Delete'!$E$35),'Reference Tab - Do not Delete'!$D$36,IF(AND(E39>='Reference Tab - Do not Delete'!$E$37,E39<'Reference Tab - Do not Delete'!$E$36),'Reference Tab - Do not Delete'!$D$37,IF(AND(E39>='Reference Tab - Do not Delete'!$E$38,E39<'Reference Tab - Do not Delete'!$E$37),'Reference Tab - Do not Delete'!$D$38,'Reference Tab - Do not Delete'!$D$39))))) -> $50B - $B | AH39: =IF(H39="","DNA",IF(H39<=10,"Top 10",IF(AND(H39<=25,H39>10),"11 - 25",IF(AND(H39<=50,H39>25),"26 - 50","Above 50")))) -> 26 - 50 | AI39: =IF(AJ39>0,"Yes","") | AJ39: 0
A40: Roopak | B40: Zurich Ins US PC Group | C40: 34 | D40: Carrier | E40: 3657532000 | F40: -0.067 | G40: 34 | H40: 29 | I40: US | J40: 96.4 | K40: Strategic | L40: Raish Malik | M40: Kathleen Savio | N40: Peter Hirs | O40: Colleen Zitt | P40: Paul Lavelle | Q40: Anurag Batta | R40: Mark Knipfer | S40: Brandin Fick | T40: Yes | U40: CTS, Genpact, Mphasis,Hinduja | V40: 44562 | AG40: =IF(E40="","",IF(E40>='Reference Tab - Do not Delete'!$E$35,'Reference Tab - Do not Delete'!$D$35,IF(AND(E40>='Reference Tab - Do not Delete'!$E$36,E40<'Reference Tab - Do not Delete'!$E$35),'Reference Tab - Do not Delete'!$D$36,IF(AND(E40>='Reference Tab - Do not Delete'!$E$37,E40<'Reference Tab - Do not Delete'!$E$36),'Reference Tab - Do not Delete'!$D$37,IF(AND(E40>='Reference Tab - Do not Delete'!$E$38,E40<'Reference Tab - Do not Delete'!$E$37),'Reference Tab - Do not Delete'!$D$38,'Reference Tab - Do not Delete'!$D$39))))) -> $50B - $B | AH40: =IF(H40="","DNA",IF(H40<=10,"Top 10",IF(AND(H40<=25,H40>10),"11 - 25",IF(AND(H40<=50,H40>25),"26 - 50","Above 50")))) -> 26 - 50 | AI40: =IF(AJ40>0,"Yes","") -> Yes | AJ40: 16435351 | AK40: Medium | AL40: Yes
A41: Roopak | B41: Assurant US PC Companies | C41: 35 | D41: Carrier | E41: 3000087000 | F41: -0.067 | G41: 35 | H41: 35 | I41: US | K41: Strategic | L41: Dushyant | AG41: =IF(E41="","",IF(E41>='Reference Tab - Do not Delete'!$E$35,'Reference Tab - Do not Delete'!$D$35,IF(AND(E41>='Reference Tab - Do not Delete'!$E$36,E41<'Reference Tab - Do not Delete'!$E$35),'Reference Tab - Do not Delete'!$D$36,IF(AND(E41>='Reference Tab - Do not Delete'!$E$37,E41<'Reference Tab - Do not Delete'!$E$36),'Reference Tab - Do not Delete'!$D$37,IF(AND(E41>='Reference Tab - Do not Delete'!$E$38,E41<'Reference Tab - Do not Delete'!$E$37),'Reference Tab - Do not Delete'!$D$38,'Reference Tab - Do not Delete'!$D$39))))) -> $50B - $B | AH41: =IF(H41="","DNA",IF(H41<=10,"Top 10",IF(AND(H41<=25,H41>10),"11 - 25",IF(AND(H41<=50,H41>25),"26 - 50","Above 50")))) -> 26 - 50 | AI41: =IF(AJ41>0,"Yes","") -> Yes | AJ41: 1064018.1
B42: QBE North America Ins Group | C42: 36 | D42: Carrier | E42: 2937088000 | F42: 0.048 | G42: 36 | H42: 38 | I42: US | T42: Yes | AG42: =IF(E42="","",IF(E42>='Reference Tab - Do not Delete'!$E$35,'Reference Tab - Do not Delete'!$D$35,IF(AND(E42>='Reference Tab - Do not Delete'!$E$36,E42<'Reference Tab - Do not Delete'!$E$35),'Reference Tab - Do not Delete'!$D$36,IF(AND(E42>='Reference Tab - Do not Delete'!$E$37,E42<'Reference Tab - Do not Delete'!$E$36),'Reference Tab - Do not Delete'!$D$37,IF(AND(E42>='Reference Tab - Do not Delete'!$E$38,E42<'Reference Tab - Do not Delete'!$E$37),'Reference Tab - Do not Delete'!$D$38,'Reference Tab - Do not Delete'!$D$39))))) -> $50B - $B | AH42: =IF(H42="","DNA",IF(H42<=10,"Top 10",IF(AND(H42<=25,H42>10),"11 - 25",IF(AND(H42<=50,H42>25),"26 - 50","Above 50")))) -> 26 - 50 | AI42: =IF(AJ42>0,"Yes","") -> Yes | AJ42: 585523.87
...

Sheet Buyer Priorities
A1: Mapping Client Priorities - VOC to Solution
A2: The following table provides a consolidated view of all the Strategic Priorities for some of the Top Insurers and Brokers. These priorities (VOC) have been mapped to various EXL solution components to focus on future priorities
A5: Home | F5: VOC | I5: VOC Translation | J5: EXL Solution
A6: Client | B6: C-Level Designation | C6: C-Level Name | D6: Location | E6: EXL - CE | F6: VOC-Source | G6: Priority - Area | H6: Priority - Sub Area | I6: Opportunity | J6: Sign Off - Next Steps/ Delete | K6: EXL - Solution | L6: EXL - Solution Component | M6: Solution Life Cycle | T6: EXL - Solution
A7: Travelers Group | B7: CEO | C7: =IF(A7="","",INDEX('Top Insurers and Brokers'!$B$7:$AF$231,(VLOOKUP(A7,'Top Insurers and Brokers'!$B$7:$C$231,2,0)),VLOOKUP(B7,$AV$9:$AW$15,2,0))) -> Alan Schnitzer | D7: =IF(A7="","",VLOOKUP(A7,'Top Insurers and Brokers'!$B$7:$I$131,8,0)) -> US | E7: =IF(A7="","",VLOOKUP(A7,'Top Insurers and Brokers'!$B$7:$AB$131,11,0)) -> Sean | F7: Press Release | G7: Strong Top Line Performance | H7: Extending our advantage in risk expertise | M7: Not Initiated | T7: FNOL | W7: FNOL | X7: Omni Channel Intake
A8: Travelers Group | B8: CEO | C8: =IF(A8="","",INDEX('Top Insurers and Brokers'!$B$7:$AF$231,(VLOOKUP(A8,'Top Insurers and Brokers'!$B$7:$C$231,2,0)),VLOOKUP(B8,$AV$9:$AW$15,2,0))) -> Alan Schnitzer | D8: =IF(A8="","",VLOOKUP(A8,'Top Insurers and Brokers'!$B$7:$I$131,8,0)) -> US | E8: =IF(A8="","",VLOOKUP(A8,'Top Insurers and Brokers'!$B$7:$AB$131,11,0)) -> Sean | F8: Press Release | G8: Optimizing Operating Leverage | H8: Providing great experiences for our customers, agents and brokers and employees | M8: Not Initiated | T8: PaaS | W8: FNOL | X8: Automated Entry FNOL capability (Thin Human/Heavy Digital)
A9: Travelers Group | B9: CEO | C9: =IF(A9="","",INDEX('Top Insurers and Brokers'!$B$7:$AF$231,(VLOOKUP(A9,'Top Insurers and Brokers'!$B$7:$C$231,2,0)),VLOOKUP(B9,$AV$9:$AW$15,2,0))) -> Alan Schnitzer | D9: =IF(A9="","",VLOOKUP(A9,'Top Insurers and Brokers'!$B$7:$I$131,8,0)) -> US | E9: =IF(A9="","",VLOOKUP(A9,'Top Insurers and Brokers'!$B$7:$AB$131,11,0)) -> Sean | F9: Press Release | G9: Optimizing Operating Leverage | H9: Optimizing our productivity and efficiency | K9: FNOL | L9: Administrative Support and Services | M9: Not Initiated | T9: DT-WC | W9: FNOL | X9: Voice Center of Excellence (COE) | AV9: CEO | AW9: 12
A10: Travelers Group | B10: CEO | C10: =IF(A10="","",INDEX('Top Insurers and Brokers'!$B$7:$AF$231,(VLOOKUP(A10,'Top Insurers and Brokers'!$B$7:$C$231,2,0)),VLOOKUP(B10,$AV$9:$AW$15,2,0))) -> Alan Schnitzer | D10: =IF(A10="","",VLOOKUP(A10,'Top Insurers and Brokers'!$B$7:$I$131,8,0)) -> US | E10: =IF(A10="","",VLOOKUP(A10,'Top Insurers and Brokers'!$B$7:$AB$131,11,0)) -> Sean | F10: Press Release | G10: Growing Investment Portfolio | T10: NB-PaaS | W10: FNOL | X10: Predictive Analytics | AV10: CFO | AW10: 13
A11: Travelers Group | C11: =IF(A11="","",INDEX('Top Insurers and Brokers'!$B$7:$AF$231,(VLOOKUP(A11,'Top Insurers and Brokers'!$B$7:$C$231,2,0)),VLOOKUP(B11,$AV$9:$AW$15,2,0))) -> #N/A | D11: =IF(A11="","",VLOOKUP(A11,'Top Insurers and Brokers'!$B$7:$I$131,8,0)) -> US | E11: =IF(A11="","",VLOOKUP(A11,'Top Insurers and Brokers'!$B$7:$AB$131,11,0)) -> Sean | F11: RM-Meet | G11: Strong Top Line Performance | H11: Extending our advantage in risk expertise | K11: NB_PaaS | L11: Rating | M11: Not Initiated | T11: E-E2E | W11: FNOL | X11: Cloud Hosted | AV11: CRO | AW11: 14
A12: Travelers Group | C12: =IF(A12="","",INDEX('Top Insurers and Brokers'!$B$7:$AF$231,(VLOOKUP(A12,'Top Insurers and Brokers'!$B$7:$C$231,2,0)),VLOOKUP(B12,$AV$9:$AW$15,2,0))) -> #N/A | D12: =IF(A12="","",VLOOKUP(A12,'Top Insurers and Brokers'!$B$7:$I$131,8,0)) -> US | E12: =IF(A12="","",VLOOKUP(A12,'Top Insurers and Brokers'!$B$7:$AB$131,11,0)) -> Sean | F12: RM-Meet | G12: Strong Top Line Performance | H12: Extending our advantage in risk expertise | K12: NB_PaaS | L12: Analytics Insights and Reporting | M12: Not Initiated | T12: BIE | W12: FNOL | X12: Speech Analytics | AV12: CCO | AW12: 15
A13: Travelers Group | C13: =IF(A13="","",INDEX('Top Insurers and Brokers'!$B$7:$AF$231,(VLOOKUP(A13,'Top Insurers and Brokers'!$B$7:$C$231,2,0)),VLOOKUP(B13,$AV$9:$AW$15,2,0))) -> #N/A | D13: =IF(A13="","",VLOOKUP(A13,'Top Insurers and Brokers'!$B$7:$I$131,8,0)) -> US | E13: =IF(A13="","",VLOOKUP(A13,'Top Insurers and Brokers'!$B$7:$AB$131,11,0)) -> Sean | F13: RM-Meet | G13: Strong Top Line Performance | H13: Extending our advantage in risk expertise | K13: NB_PaaS | L13: Submission to Quote | M13: Not Initiated | T13: Int-Col | W13: PaaS | X13: Content Extraction | AV13: COO | AW13: 16
A14: Travelers Group | C14: =IF(A14="","",INDEX('Top Insurers and Brokers'!$B$7:$AF$231,(VLOOKUP(A14,'Top Insurers and Brokers'!$B$7:$C$231,2,0)),VLOOKUP(B14,$AV$9:$AW$15,2,0))) -> #N/A | D14: =IF(A14="","",VLOOKUP(A14,'Top Insurers and Brokers'!$B$7:$I$131,8,0)) -> US | E14: =IF(A14="","",VLOOKUP(A14,'Top Insurers and Brokers'!$B$7:$AB$131,11,0)) -> Sean | F14: RM-Meet | G14: Optimizing Operating Leverage | H14: Optimizing our productivity and efficiency | K14: E_E2E | L14: End to End Endorsement Processing | M14: Not Initiated | T14: Audit-ATC | W14: PaaS | X14: Payee Portal | AV14: CIO/CTO | AW14: 17
A15: Travelers Group | C15: =IF(A15="","",INDEX('Top Insurers and Brokers'!$B$7:$AF$231,(VLOOKUP(A15,'Top Insurers and Brokers'!$B$7:$C$231,2,0)),VLOOKUP(B15,$AV$9:$AW$15,2,0))) -> #N/A | D15: =IF(A15="","",VLOOKUP(A15,'Top Insurers and Brokers'!$B$7:$I$131,8,0)) -> US | E15: =IF(A15="","",VLOOKUP(A15,'Top Insurers and Brokers'!$B$7:$AB$131,11,0)) -> Sean | F15: RM-Meet | G15: Optimizing Operating Leverage | H15: Providing great experiences for our customers, agents and brokers and employees | K15: FNOL | L15: Omni Channel Intake | M15: Not Initiated | T15: PRA | W15: PaaS | X15: Transactional Servicing Features | AV15: CUO | AW15: 18
A16: Travelers Group | C16: =IF(A16="","",INDEX('Top Insurers and Brokers'!$B$7:$AF$231,(VLOOKUP(A16,'Top Insurers and Brokers'!$B$7:$C$231,2,0)),VLOOKUP(B16,$AV$9:$AW$15,2,0))) -> #N/A | D16: =IF(A16="","",VLOOKUP(A16,'Top Insurers and Brokers'!$B$7:$I$131,8,0)) -> US | E16: =IF(A16="","",VLOOKUP(A16,'Top Insurers and Brokers'!$B$7:$AB$131,11,0)) -> Sean | F16: RM-Meet | G16: Optimizing Operating Leverage | H16: Providing great experiences for our customers, agents and brokers and employees | K16: FNOL | L16: Automated Entry FNOL capability (Thin Human/Heavy Digital) | M16: Not Initiated | T16: Fin-Auto | W16: PaaS | X16: Administrative Support and Services
A17: Travelers Group | C17: =IF(A17="","",INDEX('Top Insurers and Brokers'!$B$7:$AF$231,(VLOOKUP(A17,'Top Insurers and Brokers'!$B$7:$C$231,2,0)),VLOOKUP(B17,$AV$9:$AW$15,2,0))) -> #N/A | D17: =IF(A17="","",VLOOKUP(A17,'Top Insurers and Brokers'!$B$7:$I$131,8,0)) -> US | E17: =IF(A17="","",VLOOKUP(A17,'Top Insurers and Brokers'!$B$7:$AB$131,11,0)) -> Sean | F17: RM-Meet | G17: Strong Top Line Performance | H17: Extending our advantage in risk expertise | K17: FNOL | L17: Predictive Analytics | M17: Not Initiated | T17: TrRFF | W17: DT-WC | X17: Medical Case Management Platform
A18: Travelers Group | C18: =IF(A18="","",INDEX('Top Insurers and Brokers'!$B$7:$AF$231,(VLOOKUP(A18,'Top Insurers and Brokers'!$B$7:$C$231,2,0)),VLOOKUP(B18,$AV$9:$AW$15,2,0))) -> #N/A | D18: =IF(A18="","",VLOOKUP(A18,'Top Insurers and Brokers'!$B$7:$I$131,8,0)) -> US | E18: =IF(A18="","",VLOOKUP(A18,'Top Insurers and Brokers'!$B$7:$AB$131,11,0)) -> Sean | F18: RM-Meet | G18: Optimizing Operating Leverage | H18: Providing great experiences for our customers, agents and brokers and employees | K18: FNOL | L18: Conversational IVR | M18: Not Initiated | W18: DT-WC | X18: Automated Entry Medical Record and Bill Management capability (Thin Human/Heavy Digital).
A19: Travelers Group | C19: =IF(A19="","",INDEX('Top Insurers and Brokers'!$B$7:$AF$231,(VLOOKUP(A19,'Top Insurers and Brokers'!$B$7:$C$231,2,0)),VLOOKUP(B19,$AV$9:$AW$15,2,0))) -> #N/A | D19: =IF(A19="","",VLOOKUP(A19,'Top Insurers and Brokers'!$B$7:$I$131,8,0)) -> US | E19: =IF(A19="","",VLOOKUP(A19,'Top Insurers and Brokers'!$B$7:$AB$131,11,0)) -> Sean | F19: RM-Meet | G19: Optimizing Operating Leverage | H19: Optimizing our productivity and efficiency | K19: Int_Col | L19: Analytics Led Risk Prioritization & Forecasting | M19: Not Initiated | W19: DT-WC | X19: End to End Utilization Review
A20: Travelers Group | C20: =IF(A20="","",INDEX('Top Insurers and Brokers'!$B$7:$AF$231,(VLOOKUP(A20,'Top Insurers and Brokers'!$B$7:$C$231,2,0)),VLOOKUP(B20,$AV$9:$AW$15,2,0))) -> #N/A | D20: =IF(A20="","",VLOOKUP(A20,'Top Insurers and Brokers'!$B$7:$I$131,8,0)) -> US | E20: =IF(A20="","",VLOOKUP(A20,'Top Insurers and Brokers'!$B$7:$AB$131,11,0)) -> Sean | F20: RM-Meet | G20: Optimizing Operating Leverage | H20: Optimizing our productivity and efficiency | K20: Int_Col | L20: Real Time Cash Application | M20: Not Initiated | W20: DT-WC | X20: Medical Bill Review Capability/Platform
A21: Allstate Ins Group | C21: =IF(A21="","",INDEX('Top Insurers and Brokers'!$B$7:$AF$231,(VLOOKUP(A21,'Top Insurers and Brokers'!$B$7:$C$231,2,0)),VLOOKUP(B21,$AV$9:$AW$15,2,0))) -> #N/A | D21: =IF(A21="","",VLOOKUP(A21,'Top Insurers and Brokers'!$B$7:$I$131,8,0)) -> US | E21: =IF(A21="","",VLOOKUP(A21,'Top Insurers and Brokers'!$B$7:$AB$131,11,0)) -> Amit Gaba | F21: Other | G21: Transformative Growth Plan | H21: Expand Customer Access | W21: DT-WC | X21: Predictive Analytics Models
A22: Allstate Ins Group | C22: =IF(A22="","",INDEX('Top Insurers and Brokers'!$B$7:$AF$231,(VLOOKUP(A22,'Top Insurers and Brokers'!$B$7:$C$231,2,0)),VLOOKUP(B22,$AV$9:$AW$15,2,0))) -> #N/A | D22: =IF(A22="","",VLOOKUP(A22,'Top Insurers and Brokers'!$B$7:$I$131,8,0)) -> US | E22: =IF(A22="","",VLOOKUP(A22,'Top Insurers and Brokers'!$B$7:$AB$131,11,0)) -> Amit Gaba | F22: Other | G22: Transformative Growth Plan | H22: Enhance Customer Value Proposition | W22: DT-WC | X22: STP Modeling and Automation (Medical Only Claims)
A23: Allstate Ins Group | C23: =IF(A23="","",INDEX('Top Insurers and Brokers'!$B$7:$AF$231,(VLOOKUP(A23,'Top Insurers and Brokers'!$B$7:$C$231,2,0)),VLOOKUP(B23,$AV$9:$AW$15,2,0))) -> #N/A | D23: =IF(A23="","",VLOOKUP(A23,'Top Insurers and Brokers'!$B$7:$I$131,8,0)) -> US | E23: =IF(A23="","",VLOOKUP(A23,'Top Insurers and Brokers'!$B$7:$AB$131,11,0)) -> Amit Gaba | F23: Other | G23: Transformative Growth Plan | H23: Invest in Marketing & Technology | W23: DT-WC | X23: Payment Integrity
A24: Allstate Ins Group | C24: =IF(A24="","",INDEX('Top Insurers and Brokers'!$B$7:$AF$231,(VLOOKUP(A24,'Top Insurers and Brokers'!$B$7:$C$231,2,0)),VLOOKUP(B24,$AV$9:$AW$15,2,0))) -> #N/A | D24: =IF(A24="","",VLOOKUP(A24,'Top Insurers and Brokers'!$B$7:$I$131,8,0)) -> US | E24: =IF(A24="","",VLOOKUP(A24,'Top Insurers and Brokers'!$B$7:$AB$131,11,0)) -> Amit Gaba | F24: Other | G24: Increase Market Share in P&C | H24: Grow exclusive Agencies and Direct Channels | W24: NB-PaaS | X24: Submission to Quote
A25: Allstate Ins Group | C25: =IF(A25="","",INDEX('Top Insurers and Brokers'!$B$7:$AF$231,(VLOOKUP(A25,'Top Insurers and Brokers'!$B$7:$C$231,2,0)),VLOOKUP(B25,$AV$9:$AW$15,2,0))) -> #N/A | D25: =IF(A25="","",VLOOKUP(A25,'Top Insurers and Brokers'!$B$7:$I$131,8,0)) -> US | E25: =IF(A25="","",VLOOKUP(A25,'Top Insurers and Brokers'!$B$7:$AB$131,11,0)) -> Amit Gaba | F25: Other | G25: Increase Market Share in P&C | H25: Leverage Best-in-Class Operational capabilities | W25: NB-PaaS | X25: Rating
A26: CNA Ins Cos | C26: =IF(A26="","",INDEX('Top Insurers and Brokers'!$B$7:$AF$231,(VLOOKUP(A26,'Top Insurers and Brokers'!$B$7:$C$231,2,0)),VLOOKUP(B26,$AV$9:$AW$15,2,0))) -> #N/A | D26: =IF(A26="","",VLOOKUP(A26,'Top Insurers and Brokers'!$B$7:$I$131,8,0)) -> US | E26: Rup Goswami | F26: Press Release | G26: Sustain a deep UW Culture | H26: Elevate employee execution - continuous training, performance management and governance to support the achievement of top quartile performance | W26: NB-PaaS | X26: Analytics Insights and Reporting
A27: CNA Ins Cos | C27: =IF(A27="","",INDEX('Top Insurers and Brokers'!$B$7:$AF$231,(VLOOKUP(A27,'Top Insurers and Brokers'!$B$7:$C$231,2,0)),VLOOKUP(B27,$AV$9:$AW$15,2,0))) -> #N/A | D27: =IF(A27="","",VLOOKUP(A27,'Top Insurers and Brokers'!$B$7:$I$131,8,0)) -> US | E27: Rup Goswami | F27: Press Release | G27: Optimizing distribution engagement | H27: Build effective alignment with distribution partners - product expertise, industry specialization and overall value proposition. | W27: =T10 -> NB-PaaS | X27: End to End Endorsement Processing
A28: CNA Ins Cos | C28: =IF(A28="","",INDEX('Top Insurers and Brokers'!$B$7:$AF$231,(VLOOKUP(A28,'Top Insurers and Brokers'!$B$7:$C$231,2,0)),VLOOKUP(B28,$AV$9:$AW$15,2,0))) -> #N/A | D28: =IF(A28="","",VLOOKUP(A28,'Top Insurers and Brokers'!$B$7:$I$131,8,0)) -> US | E28: Rup Goswami | F28: Press Release | G28: Attracting, developing and retaining top talent | H28: Invest in our people to create advantage and improve performance | W28: BIE | X28: Data Ingestion from Broker Platforms
A29: CNA Ins Cos | C29: =IF(A29="","",INDEX('Top Insurers and Brokers'!$B$7:$AF$231,(VLOOKUP(A29,'Top Insurers and Brokers'!$B$7:$C$231,2,0)),VLOOKUP(B29,$AV$9:$AW$15,2,0))) -> #N/A | D29: =IF(A29="","",VLOOKUP(A29,'Top Insurers and Brokers'!$B$7:$I$131,8,0)) -> US | E29: Rup Goswami | F29: Press Release | G29: Institutionalizing deep specialization | H29: Provide insurance solutions supported by value chains of technical expertise aligned around industry segments, products and exposures | W29: BIE | X29: Data Extraction Module
C30: =IF(A30="","",INDEX('Top Insurers and Brokers'!$B$7:$AF$231,(VLOOKUP(A30,'Top Insurers and Brokers'!$B$7:$C$231,2,0)),VLOOKUP(B30,$AV$9:$AW$15,2,0))) | D30: =IF(A30="","",VLOOKUP(A30,'Top Insurers and Brokers'!$B$7:$I$131,8,0)) | E30: =IF(A30="","",VLOOKUP(A30,'Top Insurers and Brokers'!$B$7:$AB$131,11,0)) | W30: BIE | X30: Value Add Services
C31: =IF(A31="","",INDEX('Top Insurers and Brokers'!$B$7:$AF$231,(VLOOKUP(A31,'Top Insurers and Brokers'!$B$7:$C$231,2,0)),VLOOKUP(B31,$AV$9:$AW$15,2,0))) | D31: =IF(A31="","",VLOOKUP(A31,'Top Insurers and Brokers'!$B$7:$I$131,8,0)) | E31: =IF(A31="","",VLOOKUP(A31,'Top Insurers and Brokers'!$B$7:$AB$131,11,0)) | W31: Int-Col | X31: Analytics Led Risk Prioritization & Forecasting
